Workbook

Sheet HDSD
A1: Đổi định dạng ngày trên hệ thống máy tính (Windows)
A2: Đây là bước quan trọng nhất vì Excel sẽ lấy định dạng mặc định từ hệ thống máy tính của bạn.
A3: 1. Bấm phím Windows trên bàn phím (hoặc click vào nút Start), gõ chữ Control Panel và mở ứng dụng này lên.
A4: 2. Tại mục View by ở góc trên bên phải, chọn Category. Sau đó bấm vào Clock and Region (Đồng hồ và Vùng) > Chọn tiếp Region (Vùng).
A5: 3. Một hộp thoại sẽ hiện ra, tại thẻ Formats:
A6: Mục Format: Bạn có thể chọn Vietnamese (Vietnam) hoặc English (United Kingdom).
A7: Mục Short date (Ngày ngắn): Bạn click vào mũi tên trỏ xuống và chọn dd/MM/yyyy (nếu không có sẵn, bạn có thể bôi đen và gõ trực tiếp chữ dd/MM/yyyy vào ô này).
A8: (Lưu ý: Chữ 'M' viết hoa để hệ thống phân biệt với 'm' là phút).
A9: 4. Bấm Apply rồi chọn OK.
A10: Sau bước này, khi bạn nhìn xuống góc dưới cùng bên phải màn hình máy tính (chỗ hiển thị đồng hồ), bạn sẽ thấy ngày tháng đã được chuyển về chuẩn Việt Nam.
A12: Nhập dữ liệu
A13: - Chỉ nhập thông tin cho các sheet "KHÓA HỌC", "THÔNG TIN HV","ĐIỂM"
... A16: Điều chỉnh trước khi in

Sheet THỐNG KÊ
B2: THÔNG TIN LỚP HỌC | I2: THỐNG KÊ LỚP HỌC
C3: Tên nghề đào tạo | E3: Chăm sóc cà phê Vối | I3: Nội dung thống kê | K3: Nhập học | L3: Tốt nghiệp
C4: Khóa | E4: 1 | I4: Tổng số học viên | K4: =SUM(K5:K9) | L4: =COUNTIF('Thông tin HV'!Z4:Z38,"x")
C5: Năm đào tạo | E5: 2019 | I5: Nhóm đối tượng | J5: 1 | K5: =COUNTIF('Thông tin HV'!$M$4:$M$38,J5) | L5: =COUNTIF(#REF!,J5)
C6: Địa điểm đào tạo | D6: Xã: | E6: ĐăkTrăm | J6: 2 | K6: =COUNTIF('Thông tin HV'!$M$4:$M$38,J6) | L6: =COUNTIF(#REF!,J6)
D7: Huyện: | E7: =VLOOKUP(E6,#REF!,2,0) | J7: 3 | K7: =COUNTIF('Thông tin HV'!$M$4:$M$38,J7) | L7: =COUNTIFS('Thông tin HV'!Z4:Z38,"x",'Thông tin HV'!L4:L38,"Người dân tộc thiểu số")
C8: Là nghề | E8: =VLOOKUP(E3,IDs!$B$4:$C$33,2,1) | J8: 4 | K8: =COUNTIF('Thông tin HV'!$M$4:$M$38,J8) | L8: =COUNTIF(#REF!,J8)
J9: 5 | K9: =COUNTIF('Thông tin HV'!$M$4:$M$38,J9) | L9: =COUNTIF(#REF!,J9)
I10: Nữ | K10: =COUNTIF('Thông tin HV'!$E$4:$E$38,"Nữ") | L10: =COUNTIFS('Thông tin HV'!Z4:Z38,"x",'Thông tin HV'!E4:E38,"Nữ")
B11: CÔNG CỤ TẠO HỒ SƠ LỚP ĐÀO TẠO NGHỀ | I11: Dân tộc thiểu số | K11: =COUNTIF('Thông tin HV'!L4:L38,"Người dân tộc thiểu số") | L11: =COUNTIFS('Thông tin HV'!Z4:Z36,"x",'Thông tin HV'!L4:L36,"Người dân tộc thiểu số")
B12: 1 | C12: Quyết định mở lớp | I12: Nữ dân tộc thiểu số | K12: =COUNTIFS('Thông tin HV'!L4:L38,"Người dân tộc thiểu số",'Thông tin HV'!E4:E38,"Nữ") | L12: =COUNTIFS('Thông tin HV'!Z4:Z38,"x",'Thông tin HV'!L4:L38,"Người dân tộc thiểu số",'Thông tin HV'!E4:E38,"Nữ")
B13: 2 | C13: Quyết định điều động | I13: Thanh niên | K13: =COUNTIF('Thông tin HV'!I4:I38,"x") | L13: =COUNTIFS('Thông tin HV'!Z4:Z38,"x",'Thông tin HV'!I4:I38,"X")
B14: 3 | C14: Quyết định thành lập BQL lớp | I14: Thanh niên DTTS | K14: =COUNTIF('Thông tin HV'!J4:J38,"x") | L14: =COUNTIFS('Thông tin HV'!Z4:Z38,"x",'Thông tin HV'!J4:J38,"X")
B15: 4 | C15: Quyết định thành lập Hội đồng KT KTKH | I15: Tốt nghiệp THCS | J15: Tổng | K15: =COUNTIF('Thông tin HV'!K4:K38,">=9") | L15: =COUNTIFS('Thông tin HV'!K4:K38,">=9",'Thông tin HV'!Z4:Z38,"x")
B16: 5 | C16: Biên bản họp Hội đồng lần 1 | J16: Nữ | K16: =COUNTIFS('Thông tin HV'!K4:K38,">=9",'Thông tin HV'!E4:E38,"Nữ") | L16: =COUNTIFS('Thông tin HV'!Z4:Z38,"x",'Thông tin HV'!K4:K38,">=9",'Thông tin HV'!E4:E38,"Nữ")
B17: 6 | C17: Bản phân công | J17: DTTS | K17: =COUNTIFS('Thông tin HV'!K4:K38,">=9",'Thông tin HV'!L4:L38,"Người dân tộc thiểu số") | L17: =COUNTIFS('Thông tin HV'!L4:L38,"Người dân tộc thiểu số",'Thông tin HV'!Z4:Z38,"x",'Thông tin HV'!K4:K38,">=9")
B18: 7 | C18: Biên bản họp Hội đồng Thi lại | I18: Từ 25 tuổi trở xuống | J18: Tổng | K18: =COUNTIF('Thông tin HV'!D4:D38,">=1994") | L18: =COUNTIFS('Thông tin HV'!Z4:Z38,"x",'Thông tin HV'!AA4:AA38,"<=25")
B19: 8 | C19: Biên bản họp Hội đồng lần 2 | J19: Nữ | K19: =COUNTIFS('Thông tin HV'!D4:D38,">=1994",'Thông tin HV'!E4:E38,"Nữ") | L19: =COUNTIFS('Thông tin HV'!Z4:Z38,"x",'Thông tin HV'!E4:E38,"Nữ,'Thông tin hoc sinh'!D3:D37, "<="25")
B20: 9 | C20: Quyết định công nhận tốt nghiệp | J20: DTTS | K20: =COUNTIFS('Thông tin HV'!D4:D38,">=1994",'Thông tin HV'!L4:L38,"Người dân tộc thiểu số") | L20: =COUNTIFS('Thông tin HV'!Z4:Z38,"x",'Thông tin HV'!L4:L38,"Người dân tộc thiểu số",'Thông tin HV'!AA4:AA38,"<=25")
B21: 10 | C21: Quyết định khen thưởng | I21: Từ 26 - 45 tuổi | J21: Tổng | K21: =COUNTIFS('Thông tin HV'!D4:D38,"<1994",'Thông tin HV'!D4:D38,">=1973") | L21: =COUNTIFS('Thông tin HV'!Z4:Z38,"x",'Thông tin HV'!AA4:AA38,">25",'Thông tin HV'!AA4:AA38,"<=45")
J22: Nữ | K22: =COUNTIFS('Thông tin HV'!D4:D38,"<1994",'Thông tin HV'!D4:D38,">=1973",'Thông tin HV'!E4:E38,"Nữ") | L22: =COUNTIFS('Thông tin HV'!D4:D38,"<1994",'Thông tin HV'!D4:D38,">=1973",'Thông tin HV'!E4:E38,"Nữ",'Thông tin HV'!Z4:Z38,"x")
C23: XẾP LOẠI TỐT NGHIỆP | J23: DTTS | K23: =COUNTIFS('Thông tin HV'!D4:D38,"<1994",'Thông tin HV'!D4:D38,">=1973",'Thông tin HV'!L4:L38,"Người dân tộc thiểu số") | L23: =COUNTIFS('Thông tin HV'!D4:D38,"<1994",'Thông tin HV'!D4:D38,">=1973",'Thông tin HV'!L4:L38,"Người dân tộc thiểu số",'Thông tin HV'!Z4:Z38,"x")
C24: ='Công nhận tốt nghiệp'!K9 | D24: ='Công nhận tốt nghiệp'!L9 | E24: ='Công nhận tốt nghiệp'!M9 | I24: Từ 46 tuổi trở lên | J24: Tổng | K24: =COUNTIF('Thông tin HV'!D4:D38,"<1973") | L24: =COUNTIFS('Thông tin HV'!D4:D38,"<1973",'Thông tin HV'!Z4:Z38,"x")
C25: ='Công nhận tốt nghiệp'!K10 | D25: =COUNTIF('Công nhận tốt nghiệp'!G8:G38,">=8,95") | E25: ='Công nhận tốt nghiệp'!M10 | J25: Nữ | K25: =COUNTIFS('Thông tin HV'!D4:D38,"<1973",'Thông tin HV'!E4:E38,"Nữ") | L25: =COUNTIFS('Thông tin HV'!D4:D38,"<1973",'Thông tin HV'!E4:E38,"Nữ",'Thông tin HV'!Z4:Z38,"x")
C26: ='Công nhận tốt nghiệp'!K11 | D26: =COUNTIF('Công nhận tốt nghiệp'!G8:G38,">=8,0") | E26: ='Công nhận tốt nghiệp'!M11 | J26: DTTS | K26: =COUNTIFS('Thông tin HV'!D4:D38,"<1973",'Thông tin HV'!L4:L38,"Người dân tộc thiểu số") | L26: =COUNTIFS('Thông tin HV'!D4:D38,"<1973",'Thông tin HV'!L4:L38,"Người dân tộc thiểu số",'Thông tin HV'!Z4:Z38,"x")
C27: ='Công nhận tốt nghiệp'!K12 | D27: =COUNTIFS('Công nhận tốt nghiệp'!G8:G38,">=7,0",'Công nhận tốt nghiệp'!G8:G38,"<8,0") | E27: ='Công nhận tốt nghiệp'!M12
C28: ='Công nhận tốt nghiệp'!K13 | D28: =COUNTIFS('Công nhận tốt nghiệp'!G8:G39,">=6,0",'Công nhận tốt nghiệp'!G8:G39,"<7,0") | E28: ='Công nhận tốt nghiệp'!M13
C29: ='Công nhận tốt nghiệp'!K14 | D29: =COUNTIFS('Công nhận tốt nghiệp'!G8:G40,">=5,0",'Công nhận tốt nghiệp'!G8:G40,"<6,0") | E29: ='Công nhận tốt nghiệp'!M14

Sheet KHÓA HỌC
B2: THÔNG TIN VỀ KHÓA HỌC
B3: Tên khóa học | D3: 01
B4: Năm đào tạo | D4: 2026
B5: Tên nghề đào tạo | D5: Trồng và chăm sóc cà phê
B6: Thời gian đào tạo
C7: Số tháng | D7: 2
C8: Từ ngày | D8: 46157
C9: Đến ngày | D9: 15/7/2026
B10: Giáo viên chủ nhiệm
B11: Giáo viên dạy LT
B12: Giáo viên dạy TH
B15: Địa điểm đào tạo
C16: Thôn | D16: Thôn Đăk Tô 2
C17: Xã | D17: xã Đăk Tô
C18: Tỉnh | D18: tỉnh Quảng Ngãi
B19: Mục tiêu | D19: - Kiến thức Nhấn tổ hợp phím Alt+Enter để xuống dòng
B24: Việc làm sau đào tạo | D24: Nhiều dòng văn bản
B26: Danh sách các module
C27: Mã - Tên module 1 | D27: TCC1 - Trồng cà phê
C28: Mã - Tên module 2 | D28: TCC2 - Chăm sóc cà phê
C29: Mã - Tên module 3
C30: Mã - Tên module 4
C31: Mã - Tên module 5

Sheet Thông tin HV
A2: Số TT | B2: Mã số HV | C2: Họ và tên | D2: Ngày, tháng, năm sinh | E2: Giới tính | F2: Số CC/CCCD | G2: Dân tộc | H2: Tôn giáo | I2: Thanh niên | J2: Thanh niên DTTS | K2: Trình độ văn hóa | L2: Nhóm đối tượng | N2: Nơi sinh | O2: Nguyên quán | P2: Nơi cư trú | Q2: Điện thoại liên hệ | R2: Cha | T2: Mẹ | V2: Vợ/chồng | X2: Kiểm tra tuổi | Y2: Yêu cầu về hồ sơ | Z2: Tốt nghiệp | AA2: Tuổi | AB2: Nữ DTTS | AC2: DTTS | AD2: Thanh niên | AE2: Thanh niên DTTS | AF2: Tốt nghiệp THCS | AI2: Từ 25 tuổi trở xuống | AL2: Từ 26, 45 tuổi | AO2: Từ 46 tuổi trở lên | AR2: Nữ | AS2: Nữ DTTS | AT2: DTTS | AU2: Thanh niên | AV2: Thanh niên DTTS | AW2: Tốt nghiệp THCS | AZ2: Từ 25 tuổi trở xuống | BC2: Từ 26, 45 tuổi | BF2: Từ 46 tuổi trở lên
L3: Tên đối tượng | M3: Thuộc nhóm | R3: Tên | S3: Nghề nghiệp | T3: Tên | U3: Nghề nghiệp | V3: Tên | W3: Nghề nghiệp | AF3: Tổng | AG3: Nữ | AH3: DTTS | AI3: Tổng | AJ3: Nữ | AK3: DTTS | AL3: Tổng | AM3: Nữ | AN3: DTTS | AO3: Tổng | AP3: Nữ | AQ3: DTTS | AW3: Tổng | AX3: Nữ | AY3: DTTS | AZ3: Tổng | BA3: Nữ | BB3: DTTS | BC3: Tổng | BD3: Nữ | BE3: DTTS | BF3: Tổng | BG3: Nữ | BH3: DTTS
A4: 01 | C4: A HVun | D4: 39518 | E4: Nam | G4: Xê Đăng | I4: =IF(AA4="","",IF(AA4<=30,"X","")) | J4: =IF(AND(I4="X",G4<>"Kinh"),"X","") | K4: 9 | L4: Người dân tộc thiểu số | M4: =VLOOKUP(L4,IDs!$H$3:$I$12,2,0) | N4: Thôn ĐăkTrăm, xã Kon Đào, Quảng Ngãi | O4: Thôn ĐăkTrăm, xã Kon Đào, Quảng Ngãi | P4: Thôn ĐăkTrăm, xã Kon Đào, Quảng Ngãi | X4: =IF(D4="","",IF(YEAR(TODAY())-D4<15,"Không đủ tuổi theo học",IF(AND(E4="Nam",YEAR(TODAY())-D4>60),"Quá tuổi theo học",IF(AND(E4="Nữ",YEAR(TODAY())-D4>55),"Quá tuổi theo học","Đảm bảo")))) | Y4: =IF(C4="","",IF(OR(LEFT(C4,1)="Y",LEFT(C4,1)="A"),"",IF(L4<>"Đối tượng lao động nông thôn khác","Cần hồ sơ chứng minh nhóm đối tượng",""))) | AA4: =IF(OR(D4="",'KHÓA HỌC'!$D$8=""),"",DATEDIF(D4,'KHÓA HỌC'!$D$8,"y")) | AB4: =IF(C4<>"",AND(E4="Nữ",L4="Người dân tộc thiểu số"),"") | AC4: =IF(C4<>"",L4="Người dân tộc thiểu số","") | AD4: =IF(C4<>"",'THỐNG KÊ'!$E$5-'Thông tin HV'!D4<31,"") | AE4: =IF(C4<>"",AND(AC4,AD4),"") | AF4: =IF(C4<>"",(K4>=9),"") | AG4: =IF(C4<>"",AND(AF4,E4="Nữ"),"") | AH4: =IF(C4<>"",AND(AF4,AC4),"") | AI4: =IF(C4<>"",'THỐNG KÊ'!$E$5-'Thông tin HV'!D4<26,"") | AJ4: =IF(C4<>"",AND(AI4,E4="Nữ"),"") | AK4: =IF(C4<>"",AND(AI4,AC4),"") | AL4: =IF(C4<>"",AND('THỐNG KÊ'!$E$5-'Thông tin HV'!D4>=26,'THỐNG KÊ'!$E$5-'Thông tin HV'!D4<=45),"") | AM4: =IF(C4<>"",AND(AL4,E4="Nữ"),"") | AN4: =IF(C4<>"",AND(AL4,AC4),"") | AO4: =IF(C4<>"",'THỐNG KÊ'!$E$5-'Thông tin HV'!D4>45,"") | AP4: =IF(C4<>"",AND(AO4,E4="Nữ"),"") | AQ4: =IF(C4<>"",AND(AO4,AC4),"") | AR4: =IF(C4<>"",AND(Z4="x",E4="Nữ"),"") | AS4: =IF(C4<>"",AND(Z4="x",E4="Nữ",L4="Người dân tộc thiểu số"),"") | AT4: =IF(C4<>"",AND(Z4="x",L4="Người dân tộc thiểu số"),"") | AU4: =IF(C4<>"",AND(Z4="x",'THỐNG KÊ'!$E$5-'Thông tin HV'!D4<31),"") | AV4: =IF(C4<>"",AND(Z4="x",AC4,AD4),"") | AW4: =IF(C4<>"",AND(K4>=9,Z4="x"),"") | AX4: =IF(C4<>"",AND(Z4="x",AI4,E4="Nữ"),"") | AY4: =IF(C4<>"",AND(Z4="x",AF4,AC4),"") | AZ4: =IF(C4<>"",AND(Z4="x",'THỐNG KÊ'!$E$5-'Thông tin HV'!D4<26),"") | BA4: =IF(C4<>"",AND(Z4="x",AI4,E4="Nữ"),"") | BB4: =IF(C4<>"",AND(Z4="x",AI4,AC4),"") | BC4: =IF(C4<>"",AND(Z4="x",'THỐNG KÊ'!$E$5-'Thông tin HV'!D4>=26,'THỐNG KÊ'!$E$5-'Thông tin HV'!D4<=45),"") | BD4: =IF(C4<>"",AND(Z4="x",AL4,E4="Nữ"),"") | BE4: =IF(C4<>"",AND(Z4="x",AL4,AC4),"") | BF4: =IF(C4<>"",AND(Z4="x",'THỐNG KÊ'!$E$5-'Thông tin HV'!D4>45),"") | BG4: =IF(C4<>"",AND(Z4="x",AO4,E4="Nữ"),"") | BH4: =IF(C4<>"",AND(Z4="x",AO4,AC4),"")
A5: 02 | C5: A Ngực | D5: 30386 | E5: Nam | G5: Xê Đăng | I5: =IF(AA5="","",IF(AA5<=30,"X","")) | J5: =IF(AND(I5="X",G5<>"Kinh"),"X","") | K5: 12 | L5: Người dân tộc thiểu số | M5: =VLOOKUP(L5,IDs!$H$3:$I$12,2,0) | N5: Thôn ĐăkTrăm, xã Kon Đào, Quảng Ngãi | O5: Thôn ĐăkTrăm, xã Kon Đào, Quảng Ngãi | P5: Thôn ĐăkTrăm, xã Kon Đào, Quảng Ngãi | X5: =IF(D5="","",IF(YEAR(TODAY())-D5<15,"Không đủ tuổi theo học",IF(AND(E5="Nam",YEAR(TODAY())-D5>60),"Quá tuổi theo học",IF(AND(E5="Nữ",YEAR(TODAY())-D5>55),"Quá tuổi theo học","Đảm bảo")))) | Y5: =IF(C5="","",IF(OR(LEFT(C5,1)="Y",LEFT(C5,1)="A"),"",IF(L5<>"Đối tượng lao động nông thôn khác","Cần hồ sơ chứng minh nhóm đối tượng",""))) | AA5: =IF(OR(D5="",'KHÓA HỌC'!$D$8=""),"",DATEDIF(D5,'KHÓA HỌC'!$D$8,"y")) | AB5: =IF(C5<>"",AND(E5="Nữ",L5="Người dân tộc thiểu số"),"") | AC5: =IF(C5<>"",L5="Người dân tộc thiểu số","") | AD5: =IF(C5<>"",'THỐNG KÊ'!$E$5-'Thông tin HV'!D5<31,"") | AE5: =IF(C5<>"",AND(AC5,AD5),"") | AF5: =IF(C5<>"",(K5>=9),"") | AG5: =IF(C5<>"",AND(AF5,E5="Nữ"),"") | AH5: =IF(C5<>"",AND(AF5,AC5),"") | AI5: =IF(C5<>"",'THỐNG KÊ'!$E$5-'Thông tin HV'!D5<26,"") | AJ5: =IF(C5<>"",AND(AI5,E5="Nữ"),"") | AK5: =IF(C5<>"",AND(AI5,AC5),"") | AL5: =IF(C5<>"",AND('THỐNG KÊ'!$E$5-'Thông tin HV'!D5>=26,'THỐNG KÊ'!$E$5-'Thông tin HV'!D5<=45),"") | AM5: =IF(C5<>"",AND(AL5,E5="Nữ"),"") | AN5: =IF(C5<>"",AND(AL5,AC5),"") | AO5: =IF(C5<>"",'THỐNG KÊ'!$E$5-'Thông tin HV'!D5>45,"") | AP5: =IF(C5<>"",AND(AO5,E5="Nữ"),"") | AQ5: =IF(C5<>"",AND(AO5,AC5),"") | AR5: =IF(C5<>"",AND(Z5="x",E5="Nữ"),"") | AS5: =IF(C5<>"",AND(Z5="x",E5="Nữ",L5="Người dân tộc thiểu số"),"") | AT5: =IF(C5<>"",AND(Z5="x",L5="Người dân tộc thiểu số"),"") | AU5: =IF(C5<>"",AND(Z5="x",'THỐNG KÊ'!$E$5-'Thông tin HV'!D5<31),"") | AV5: =IF(C5<>"",AND(Z5="x",AC5,AD5),"") | AW5: =IF(C5<>"",AND(K5>=9,Z5="x"),"") | AX5: =IF(C5<>"",AND(Z5="x",AI5,E5="Nữ"),"") | AY5: =IF(C5<>"",AND(Z5="x",AF5,AC5),"") | AZ5: =IF(C5<>"",AND(Z5="x",'THỐNG KÊ'!$E$5-'Thông tin HV'!D5<26),"") | BA5: =IF(C5<>"",AND(Z5="x",AI5,E5="Nữ"),"") | BB5: =IF(C5<>"",AND(Z5="x",AI5,AC5),"") | BC5: =IF(C5<>"",AND(Z5="x",'THỐNG KÊ'!$E$5-'Thông tin HV'!D5>=26,'THỐNG KÊ'!$E$5-'Thông tin HV'!D5<=45),"") | BD5: =IF(C5<>"",AND(Z5="x",AL5,E5="Nữ"),"") | BE5: =IF(C5<>"",AND(Z5="x",AL5,AC5),"") | BF5: =IF(C5<>"",AND(Z5="x",'THỐNG KÊ'!$E$5-'Thông tin HV'!D5>45),"") | BG5: =IF(C5<>"",AND(Z5="x",AO5,E5="Nữ"),"") | BH5: =IF(C5<>"",AND(Z5="x",AO5,AC5),"")
A6: 03 | C6: A Bét | D6: 30386 | E6: Nam | G6: Xê Đăng | I6: =IF(AA6="","",IF(AA6<=30,"X","")) | J6: =IF(AND(I6="X",G6<>"Kinh"),"X","") | K6: 10 | L6: Người dân tộc thiểu số | M6: =VLOOKUP(L6,IDs!$H$3:$I$12,2,0) | N6: Thôn ĐăkTrăm, xã Kon Đào, Quảng Ngãi | O6: Thôn ĐăkTrăm, xã Kon Đào, Quảng Ngãi | P6: Thôn ĐăkTrăm, xã Kon Đào, Quảng Ngãi | X6: =IF(D6="","",IF(YEAR(TODAY())-D6<15,"Không đủ tuổi theo học",IF(AND(E6="Nam",YEAR(TODAY())-D6>60),"Quá tuổi theo học",IF(AND(E6="Nữ",YEAR(TODAY())-D6>55),"Quá tuổi theo học","Đảm bảo")))) | Y6: =IF(C6="","",IF(OR(LEFT(C6,1)="Y",LEFT(C6,1)="A"),"",IF(L6<>"Đối tượng lao động nông thôn khác","Cần hồ sơ chứng minh nhóm đối tượng",""))) | AA6: =IF(OR(D6="",'KHÓA HỌC'!$D$8=""),"",DATEDIF(D6,'KHÓA HỌC'!$D$8,"y")) | AB6: =IF(C6<>"",AND(E6="Nữ",L6="Người dân tộc thiểu số"),"") | AC6: =IF(C6<>"",L6="Người dân tộc thiểu số","") | AD6: =IF(C6<>"",'THỐNG KÊ'!$E$5-'Thông tin HV'!D6<31,"") | AE6: =IF(C6<>"",AND(AC6,AD6),"") | AF6: =IF(C6<>"",(K6>=9),"") | AG6: =IF(C6<>"",AND(AF6,E6="Nữ"),"") | AH6: =IF(C6<>"",AND(AF6,AC6),"") | AI6: =IF(C6<>"",'THỐNG KÊ'!$E$5-'Thông tin HV'!D6<26,"") | AJ6: =IF(C6<>"",AND(AI6,E6="Nữ"),"") | AK6: =IF(C6<>"",AND(AI6,AC6),"") | AL6: =IF(C6<>"",AND('THỐNG KÊ'!$E$5-'Thông tin HV'!D6>=26,'THỐNG KÊ'!$E$5-'Thông tin HV'!D6<=45),"") | AM6: =IF(C6<>"",AND(AL6,E6="Nữ"),"") | AN6: =IF(C6<>"",AND(AL6,AC6),"") | AO6: =IF(C6<>"",'THỐNG KÊ'!$E$5-'Thông tin HV'!D6>45,"") | AP6: =IF(C6<>"",AND(AO6,E6="Nữ"),"") | AQ6: =IF(C6<>"",AND(AO6,AC6),"") | AR6: =IF(C6<>"",AND(Z6="x",E6="Nữ"),"") | AS6: =IF(C6<>"",AND(Z6="x",E6="Nữ",L6="Người dân tộc thiểu số"),"") | AT6: =IF(C6<>"",AND(Z6="x",L6="Người dân tộc thiểu số"),"") | AU6: =IF(C6<>"",AND(Z6="x",'THỐNG KÊ'!$E$5-'Thông tin HV'!D6<31),"") | AV6: =IF(C6<>"",AND(Z6="x",AC6,AD6),"") | AW6: =IF(C6<>"",AND(K6>=9,Z6="x"),"") | AX6: =IF(C6<>"",AND(Z6="x",AI6,E6="Nữ"),"") | AY6: =IF(C6<>"",AND(Z6="x",AF6,AC6),"") | AZ6: =IF(C6<>"",AND(Z6="x",'THỐNG KÊ'!$E$5-'Thông tin HV'!D6<26),"") | BA6: =IF(C6<>"",AND(Z6="x",AI6,E6="Nữ"),"") | BB6: =IF(C6<>"",AND(Z6="x",AI6,AC6),"") | BC6: =IF(C6<>"",AND(Z6="x",'THỐNG KÊ'!$E$5-'Thông tin HV'!D6>=26,'THỐNG KÊ'!$E$5-'Thông tin HV'!D6<=45),"") | BD6: =IF(C6<>"",AND(Z6="x",AL6,E6="Nữ"),"") | BE6: =IF(C6<>"",AND(Z6="x",AL6,AC6),"") | BF6: =IF(C6<>"",AND(Z6="x",'THỐNG KÊ'!$E$5-'Thông tin HV'!D6>45),"") | BG6: =IF(C6<>"",AND(Z6="x",AO6,E6="Nữ"),"") | BH6: =IF(C6<>"",AND(Z6="x",AO6,AC6),"")
A7: 04 | C7: A Quyết | D7: 30386 | E7: Nam | G7: Xê Đăng | I7: =IF(AA7="","",IF(AA7<=30,"X","")) | J7: =IF(AND(I7="X",G7<>"Kinh"),"X","") | K7: 9 | L7: Người dân tộc thiểu số | M7: =VLOOKUP(L7,IDs!$H$3:$I$12,2,0) | N7: Thôn ĐăkTrăm, xã Kon Đào, Quảng Ngãi | O7: Thôn ĐăkTrăm, xã Kon Đào, Quảng Ngãi | P7: Thôn ĐăkTrăm, xã Kon Đào, Quảng Ngãi | X7: =IF(D7="","",IF(YEAR(TODAY())-D7<15,"Không đủ tuổi theo học",IF(AND(E7="Nam",YEAR(TODAY())-D7>60),"Quá tuổi theo học",IF(AND(E7="Nữ",YEAR(TODAY())-D7>55),"Quá tuổi theo học","Đảm bảo")))) | Y7: =IF(C7="","",IF(OR(LEFT(C7,1)="Y",LEFT(C7,1)="A"),"",IF(L7<>"Đối tượng lao động nông thôn khác","Cần hồ sơ chứng minh nhóm đối tượng",""))) | AA7: =IF(OR(D7="",'KHÓA HỌC'!$D$8=""),"",DATEDIF(D7,'KHÓA HỌC'!$D$8,"y")) | AB7: =IF(C7<>"",AND(E7="Nữ",L7="Người dân tộc thiểu số"),"") | AC7: =IF(C7<>"",L7="Người dân tộc thiểu số","") | AD7: =IF(C7<>"",'THỐNG KÊ'!$E$5-'Thông tin HV'!D7<31,"") | AE7: =IF(C7<>"",AND(AC7,AD7),"") | AF7: =IF(C7<>"",(K7>=9),"") | AG7: =IF(C7<>"",AND(AF7,E7="Nữ"),"") | AH7: =IF(C7<>"",AND(AF7,AC7),"") | AI7: =IF(C7<>"",'THỐNG KÊ'!$E$5-'Thông tin HV'!D7<26,"") | AJ7: =IF(C7<>"",AND(AI7,E7="Nữ"),"") | AK7: =IF(C7<>"",AND(AI7,AC7),"") | AL7: =IF(C7<>"",AND('THỐNG KÊ'!$E$5-'Thông tin HV'!D7>=26,'THỐNG KÊ'!$E$5-'Thông tin HV'!D7<=45),"") | AM7: =IF(C7<>"",AND(AL7,E7="Nữ"),"") | AN7: =IF(C7<>"",AND(AL7,AC7),"") | AO7: =IF(C7<>"",'THỐNG KÊ'!$E$5-'Thông tin HV'!D7>45,"") | AP7: =IF(C7<>"",AND(AO7,E7="Nữ"),"") | AQ7: =IF(C7<>"",AND(AO7,AC7),"") | AR7: =IF(C7<>"",AND(Z7="x",E7="Nữ"),"") | AS7: =IF(C7<>"",AND(Z7="x",E7="Nữ",L7="Người dân tộc thiểu số"),"") | AT7: =IF(C7<>"",AND(Z7="x",L7="Người dân tộc thiểu số"),"") | AU7: =IF(C7<>"",AND(Z7="x",'THỐNG KÊ'!$E$5-'Thông tin HV'!D7<31),"") | AV7: =IF(C7<>"",AND(Z7="x",AC7,AD7),"") | AW7: =IF(C7<>"",AND(K7>=9,Z7="x"),"") | AX7: =IF(C7<>"",AND(Z7="x",AI7,E7="Nữ"),"") | AY7: =IF(C7<>"",AND(Z7="x",AF7,AC7),"") | AZ7: =IF(C7<>"",AND(Z7="x",'THỐNG KÊ'!$E$5-'Thông tin HV'!D7<26),"") | BA7: =IF(C7<>"",AND(Z7="x",AI7,E7="Nữ"),"") | BB7: =IF(C7<>"",AND(Z7="x",AI7,AC7),"") | BC7: =IF(C7<>"",AND(Z7="x",'THỐNG KÊ'!$E$5-'Thông tin HV'!D7>=26,'THỐNG KÊ'!$E$5-'Thông tin HV'!D7<=45),"") | BD7: =IF(C7<>"",AND(Z7="x",AL7,E7="Nữ"),"") | BE7: =IF(C7<>"",AND(Z7="x",AL7,AC7),"") | BF7: =IF(C7<>"",AND(Z7="x",'THỐNG KÊ'!$E$5-'Thông tin HV'!D7>45),"") | BG7: =IF(C7<>"",AND(Z7="x",AO7,E7="Nữ"),"") | BH7: =IF(C7<>"",AND(Z7="x",AO7,AC7),"")
A8: 05 | C8: A Phan | D8: 30386 | E8: Nam | G8: Xê Đăng | I8: =IF(AA8="","",IF(AA8<=30,"X","")) | J8: =IF(AND(I8="X",G8<>"Kinh"),"X","") | K8: 8 | L8: Người dân tộc thiểu số | M8: =VLOOKUP(L8,IDs!$H$3:$I$12,2,0) | N8: Thôn ĐăkTrăm, xã Kon Đào, Quảng Ngãi | O8: Thôn ĐăkTrăm, xã Kon Đào, Quảng Ngãi | P8: Thôn ĐăkTrăm, xã Kon Đào, Quảng Ngãi | X8: =IF(D8="","",IF(YEAR(TODAY())-D8<15,"Không đủ tuổi theo học",IF(AND(E8="Nam",YEAR(TODAY())-D8>60),"Quá tuổi theo học",IF(AND(E8="Nữ",YEAR(TODAY())-D8>55),"Quá tuổi theo học","Đảm bảo")))) | Y8: =IF(C8="","",IF(OR(LEFT(C8,1)="Y",LEFT(C8,1)="A"),"",IF(L8<>"Đối tượng lao động nông thôn khác","Cần hồ sơ chứng minh nhóm đối tượng",""))) | AA8: =IF(OR(D8="",'KHÓA HỌC'!$D$8=""),"",DATEDIF(D8,'KHÓA HỌC'!$D$8,"y")) | AB8: =IF(C8<>"",AND(E8="Nữ",L8="Người dân tộc thiểu số"),"") | AC8: =IF(C8<>"",L8="Người dân tộc thiểu số","") | AD8: =IF(C8<>"",'THỐNG KÊ'!$E$5-'Thông tin HV'!D8<31,"") | AE8: =IF(C8<>"",AND(AC8,AD8),"") | AF8: =IF(C8<>"",(K8>=9),"") | AG8: =IF(C8<>"",AND(AF8,E8="Nữ"),"") | AH8: =IF(C8<>"",AND(AF8,AC8),"") | AI8: =IF(C8<>"",'THỐNG KÊ'!$E$5-'Thông tin HV'!D8<26,"") | AJ8: =IF(C8<>"",AND(AI8,E8="Nữ"),"") | AK8: =IF(C8<>"",AND(AI8,AC8),"") | AL8: =IF(C8<>"",AND('THỐNG KÊ'!$E$5-'Thông tin HV'!D8>=26,'THỐNG KÊ'!$E$5-'Thông tin HV'!D8<=45),"") | AM8: =IF(C8<>"",AND(AL8,E8="Nữ"),"") | AN8: =IF(C8<>"",AND(AL8,AC8),"") | AO8: =IF(C8<>"",'THỐNG KÊ'!$E$5-'Thông tin HV'!D8>45,"") | AP8: =IF(C8<>"",AND(AO8,E8="Nữ"),"") | AQ8: =IF(C8<>"",AND(AO8,AC8),"") | AR8: =IF(C8<>"",AND(Z8="x",E8="Nữ"),"") | AS8: =IF(C8<>"",AND(Z8="x",E8="Nữ",L8="Người dân tộc thiểu số"),"") | AT8: =IF(C8<>"",AND(Z8="x",L8="Người dân tộc thiểu số"),"") | AU8: =IF(C8<>"",AND(Z8="x",'THỐNG KÊ'!$E$5-'Thông tin HV'!D8<31),"") | AV8: =IF(C8<>"",AND(Z8="x",AC8,AD8),"") | AW8: =IF(C8<>"",AND(K8>=9,Z8="x"),"") | AX8: =IF(C8<>"",AND(Z8="x",AI8,E8="Nữ"),"") | AY8: =IF(C8<>"",AND(Z8="x",AF8,AC8),"") | AZ8: =IF(C8<>"",AND(Z8="x",'THỐNG KÊ'!$E$5-'Thông tin HV'!D8<26),"") | BA8: =IF(C8<>"",AND(Z8="x",AI8,E8="Nữ"),"") | BB8: =IF(C8<>"",AND(Z8="x",AI8,AC8),"") | BC8: =IF(C8<>"",AND(Z8="x",'THỐNG KÊ'!$E$5-'Thông tin HV'!D8>=26,'THỐNG KÊ'!$E$5-'Thông tin HV'!D8<=45),"") | BD8: =IF(C8<>"",AND(Z8="x",AL8,E8="Nữ"),"") | BE8: =IF(C8<>"",AND(Z8="x",AL8,AC8),"") | BF8: =IF(C8<>"",AND(Z8="x",'THỐNG KÊ'!$E$5-'Thông tin HV'!D8>45),"") | BG8: =IF(C8<>"",AND(Z8="x",AO8,E8="Nữ"),"") | BH8: =IF(C8<>"",AND(Z8="x",AO8,AC8),"")
A9: 06 | C9: A Ká | D9: 30386 | E9: Nam | G9: Xê Đăng | I9: =IF(AA9="","",IF(AA9<=30,"X","")) | J9: =IF(AND(I9="X",G9<>"Kinh"),"X","") | K9: 8 | L9: Người dân tộc thiểu số | M9: =VLOOKUP(L9,IDs!$H$3:$I$12,2,0) | N9: Thôn ĐăkTrăm, xã Kon Đào, Quảng Ngãi | O9: Thôn ĐăkTrăm, xã Kon Đào, Quảng Ngãi | P9: Thôn ĐăkTrăm, xã Kon Đào, Quảng Ngãi | X9: =IF(D9="","",IF(YEAR(TODAY())-D9<15,"Không đủ tuổi theo học",IF(AND(E9="Nam",YEAR(TODAY())-D9>60),"Quá tuổi theo học",IF(AND(E9="Nữ",YEAR(TODAY())-D9>55),"Quá tuổi theo học","Đảm bảo")))) | Y9: =IF(C9="","",IF(OR(LEFT(C9,1)="Y",LEFT(C9,1)="A"),"",IF(L9<>"Đối tượng lao động nông thôn khác","Cần hồ sơ chứng minh nhóm đối tượng",""))) | AA9: =IF(OR(D9="",'KHÓA HỌC'!$D$8=""),"",DATEDIF(D9,'KHÓA HỌC'!$D$8,"y")) | AB9: =IF(C9<>"",AND(E9="Nữ",L9="Người dân tộc thiểu số"),"") | AC9: =IF(C9<>"",L9="Người dân tộc thiểu số","") | AD9: =IF(C9<>"",'THỐNG KÊ'!$E$5-'Thông tin HV'!D9<31,"") | AE9: =IF(C9<>"",AND(AC9,AD9),"") | AF9: =IF(C9<>"",(K9>=9),"") | AG9: =IF(C9<>"",AND(AF9,E9="Nữ"),"") | AH9: =IF(C9<>"",AND(AF9,AC9),"") | AI9: =IF(C9<>"",'THỐNG KÊ'!$E$5-'Thông tin HV'!D9<26,"") | AJ9: =IF(C9<>"",AND(AI9,E9="Nữ"),"") | AK9: =IF(C9<>"",AND(AI9,AC9),"") | AL9: =IF(C9<>"",AND('THỐNG KÊ'!$E$5-'Thông tin HV'!D9>=26,'THỐNG KÊ'!$E$5-'Thông tin HV'!D9<=45),"") | AM9: =IF(C9<>"",AND(AL9,E9="Nữ"),"") | AN9: =IF(C9<>"",AND(AL9,AC9),"") | AO9: =IF(C9<>"",'THỐNG KÊ'!$E$5-'Thông tin HV'!D9>45,"") | AP9: =IF(C9<>"",AND(AO9,E9="Nữ"),"") | AQ9: =IF(C9<>"",AND(AO9,AC9),"") | AR9: =IF(C9<>"",AND(Z9="x",E9="Nữ"),"") | AS9: =IF(C9<>"",AND(Z9="x",E9="Nữ",L9="Người dân tộc thiểu số"),"") | AT9: =IF(C9<>"",AND(Z9="x",L9="Người dân tộc thiểu số"),"") | AU9: =IF(C9<>"",AND(Z9="x",'THỐNG KÊ'!$E$5-'Thông tin HV'!D9<31),"") | AV9: =IF(C9<>"",AND(Z9="x",AC9,AD9),"") | AW9: =IF(C9<>"",AND(K9>=9,Z9="x"),"") | AX9: =IF(C9<>"",AND(Z9="x",AI9,E9="Nữ"),"") | AY9: =IF(C9<>"",AND(Z9="x",AF9,AC9),"") | AZ9: =IF(C9<>"",AND(Z9="x",'THỐNG KÊ'!$E$5-'Thông tin HV'!D9<26),"") | BA9: =IF(C9<>"",AND(Z9="x",AI9,E9="Nữ"),"") | BB9: =IF(C9<>"",AND(Z9="x",AI9,AC9),"") | BC9: =IF(C9<>"",AND(Z9="x",'THỐNG KÊ'!$E$5-'Thông tin HV'!D9>=26,'THỐNG KÊ'!$E$5-'Thông tin HV'!D9<=45),"") | BD9: =IF(C9<>"",AND(Z9="x",AL9,E9="Nữ"),"") | BE9: =IF(C9<>"",AND(Z9="x",AL9,AC9),"") | BF9: =IF(C9<>"",AND(Z9="x",'THỐNG KÊ'!$E$5-'Thông tin HV'!D9>45),"") | BG9: =IF(C9<>"",AND(Z9="x",AO9,E9="Nữ"),"") | BH9: =IF(C9<>"",AND(Z9="x",AO9,AC9),"")
A10: 07 | C10: A Thim | D10: 30386 | E10: Nam | G10: Xê Đăng | I10: =IF(AA10="","",IF(AA10<=30,"X","")) | J10: =IF(AND(I10="X",G10<>"Kinh"),"X","") | K10: 9 | L10: Người dân tộc thiểu số | M10: =VLOOKUP(L10,IDs!$H$3:$I$12,2,0) | N10: Thôn ĐăkTrăm, xã Kon Đào, Quảng Ngãi | O10: Thôn ĐăkTrăm, xã Kon Đào, Quảng Ngãi | P10: Thôn ĐăkTrăm, xã Kon Đào, Quảng Ngãi | X10: =IF(D10="","",IF(YEAR(TODAY())-D10<15,"Không đủ tuổi theo học",IF(AND(E10="Nam",YEAR(TODAY())-D10>60),"Quá tuổi theo học",IF(AND(E10="Nữ",YEAR(TODAY())-D10>55),"Quá tuổi theo học","Đảm bảo")))) | Y10: =IF(C10="","",IF(OR(LEFT(C10,1)="Y",LEFT(C10,1)="A"),"",IF(L10<>"Đối tượng lao động nông thôn khác","Cần hồ sơ chứng minh nhóm đối tượng",""))) | AA10: =IF(OR(D10="",'KHÓA HỌC'!$D$8=""),"",DATEDIF(D10,'KHÓA HỌC'!$D$8,"y")) | AB10: =IF(C10<>"",AND(E10="Nữ",L10="Người dân tộc thiểu số"),"") | AC10: =IF(C10<>"",L10="Người dân tộc thiểu số","") | AD10: =IF(C10<>"",'THỐNG KÊ'!$E$5-'Thông tin HV'!D10<31,"") | AE10: =IF(C10<>"",AND(AC10,AD10),"") | AF10: =IF(C10<>"",(K10>=9),"") | AG10: =IF(C10<>"",AND(AF10,E10="Nữ"),"") | AH10: =IF(C10<>"",AND(AF10,AC10),"") | AI10: =IF(C10<>"",'THỐNG KÊ'!$E$5-'Thông tin HV'!D10<26,"") | AJ10: =IF(C10<>"",AND(AI10,E10="Nữ"),"") | AK10: =IF(C10<>"",AND(AI10,AC10),"") | AL10: =IF(C10<>"",AND('THỐNG KÊ'!$E$5-'Thông tin HV'!D10>=26,'THỐNG KÊ'!$E$5-'Thông tin HV'!D10<=45),"") | AM10: =IF(C10<>"",AND(AL10,E10="Nữ"),"") | AN10: =IF(C10<>"",AND(AL10,AC10),"") | AO10: =IF(C10<>"",'THỐNG KÊ'!$E$5-'Thông tin HV'!D10>45,"") | AP10: =IF(C10<>"",AND(AO10,E10="Nữ"),"") | AQ10: =IF(C10<>"",AND(AO10,AC10),"") | AR10: =IF(C10<>"",AND(Z10="x",E10="Nữ"),"") | AS10: =IF(C10<>"",AND(Z10="x",E10="Nữ",L10="Người dân tộc thiểu số"),"") | AT10: =IF(C10<>"",AND(Z10="x",L10="Người dân tộc thiểu số"),"") | AU10: =IF(C10<>"",AND(Z10="x",'THỐNG KÊ'!$E$5-'Thông tin HV'!D10<31),"") | AV10: =IF(C10<>"",AND(Z10="x",AC10,AD10),"") | AW10: =IF(C10<>"",AND(K10>=9,Z10="x"),"") | AX10: =IF(C10<>"",AND(Z10="x",AI10,E10="Nữ"),"") | AY10: =IF(C10<>"",AND(Z10="x",AF10,AC10),"") | AZ10: =IF(C10<>"",AND(Z10="x",'THỐNG KÊ'!$E$5-'Thông tin HV'!D10<26),"") | BA10: =IF(C10<>"",AND(Z10="x",AI10,E10="Nữ"),"") | BB10: =IF(C10<>"",AND(Z10="x",AI10,AC10),"") | BC10: =IF(C10<>"",AND(Z10="x",'THỐNG KÊ'!$E$5-'Thông tin HV'!D10>=26,'THỐNG KÊ'!$E$5-'Thông tin HV'!D10<=45),"") | BD10: =IF(C10<>"",AND(Z10="x",AL10,E10="Nữ"),"") | BE10: =IF(C10<>"",AND(Z10="x",AL10,AC10),"") | BF10: =IF(C10<>"",AND(Z10="x",'THỐNG KÊ'!$E$5-'Thông tin HV'!D10>45),"") | BG10: =IF(C10<>"",AND(Z10="x",AO10,E10="Nữ"),"") | BH10: =IF(C10<>"",AND(Z10="x",AO10,AC10),"")
A11: 08 | C11: A Khinh | D11: 30386 | E11: Nam | G11: Xê Đăng | I11: =IF(AA11="","",IF(AA11<=30,"X","")) | J11: =IF(AND(I11="X",G11<>"Kinh"),"X","") | K11: 5 | L11: Người dân tộc thiểu số | M11: =VLOOKUP(L11,IDs!$H$3:$I$12,2,0) | N11: Thôn ĐăkTrăm, xã Kon Đào, Quảng Ngãi | O11: Thôn ĐăkTrăm, xã Kon Đào, Quảng Ngãi | P11: Thôn ĐăkTrăm, xã Kon Đào, Quảng Ngãi | X11: =IF(D11="","",IF(YEAR(TODAY())-D11<15,"Không đủ tuổi theo học",IF(AND(E11="Nam",YEAR(TODAY())-D11>60),"Quá tuổi theo học",IF(AND(E11="Nữ",YEAR(TODAY())-D11>55),"Quá tuổi theo học","Đảm bảo")))) | Y11: =IF(C11="","",IF(OR(LEFT(C11,1)="Y",LEFT(C11,1)="A"),"",IF(L11<>"Đối tượng lao động nông thôn khác","Cần hồ sơ chứng minh nhóm đối tượng",""))) | AA11: =IF(OR(D11="",'KHÓA HỌC'!$D$8=""),"",DATEDIF(D11,'KHÓA HỌC'!$D$8,"y")) | AB11: =IF(C11<>"",AND(E11="Nữ",L11="Người dân tộc thiểu số"),"") | AC11: =IF(C11<>"",L11="Người dân tộc thiểu số","") | AD11: =IF(C11<>"",'THỐNG KÊ'!$E$5-'Thông tin HV'!D11<31,"") | AE11: =IF(C11<>"",AND(AC11,AD11),"") | AF11: =IF(C11<>"",(K11>=9),"") | AG11: =IF(C11<>"",AND(AF11,E11="Nữ"),"") | AH11: =IF(C11<>"",AND(AF11,AC11),"") | AI11: =IF(C11<>"",'THỐNG KÊ'!$E$5-'Thông tin HV'!D11<26,"") | AJ11: =IF(C11<>"",AND(AI11,E11="Nữ"),"") | AK11: =IF(C11<>"",AND(AI11,AC11),"") | AL11: =IF(C11<>"",AND('THỐNG KÊ'!$E$5-'Thông tin HV'!D11>=26,'THỐNG KÊ'!$E$5-'Thông tin HV'!D11<=45),"") | AM11: =IF(C11<>"",AND(AL11,E11="Nữ"),"") | AN11: =IF(C11<>"",AND(AL11,AC11),"") | AO11: =IF(C11<>"",'THỐNG KÊ'!$E$5-'Thông tin HV'!D11>45,"") | AP11: =IF(C11<>"",AND(AO11,E11="Nữ"),"") | AQ11: =IF(C11<>"",AND(AO11,AC11),"") | AR11: =IF(C11<>"",AND(Z11="x",E11="Nữ"),"") | AS11: =IF(C11<>"",AND(Z11="x",E11="Nữ",L11="Người dân tộc thiểu số"),"") | AT11: =IF(C11<>"",AND(Z11="x",L11="Người dân tộc thiểu số"),"") | AU11: =IF(C11<>"",AND(Z11="x",'THỐNG KÊ'!$E$5-'Thông tin HV'!D11<31),"") | AV11: =IF(C11<>"",AND(Z11="x",AC11,AD11),"") | AW11: =IF(C11<>"",AND(K11>=9,Z11="x"),"") | AX11: =IF(C11<>"",AND(Z11="x",AI11,E11="Nữ"),"") | AY11: =IF(C11<>"",AND(Z11="x",AF11,AC11),"") | AZ11: =IF(C11<>"",AND(Z11="x",'THỐNG KÊ'!$E$5-'Thông tin HV'!D11<26),"") | BA11: =IF(C11<>"",AND(Z11="x",AI11,E11="Nữ"),"") | BB11: =IF(C11<>"",AND(Z11="x",AI11,AC11),"") | BC11: =IF(C11<>"",AND(Z11="x",'THỐNG KÊ'!$E$5-'Thông tin HV'!D11>=26,'THỐNG KÊ'!$E$5-'Thông tin HV'!D11<=45),"") | BD11: =IF(C11<>"",AND(Z11="x",AL11,E11="Nữ"),"") | BE11: =IF(C11<>"",AND(Z11="x",AL11,AC11),"") | BF11: =IF(C11<>"",AND(Z11="x",'THỐNG KÊ'!$E$5-'Thông tin HV'!D11>45),"") | BG11: =IF(C11<>"",AND(Z11="x",AO11,E11="Nữ"),"") | BH11: =IF(C11<>"",AND(Z11="x",AO11,AC11),"")
A12: 09 | C12: A Bar | D12: 30386 | E12: Nam | G12: Xê Đăng | I12: =IF(AA12="","",IF(AA12<=30,"X","")) | J12: =IF(AND(I12="X",G12<>"Kinh"),"X","") | K12: 9 | L12: Người dân tộc thiểu số | M12: =VLOOKUP(L12,IDs!$H$3:$I$12,2,0) | N12: Thôn ĐăkTrăm, xã Kon Đào, Quảng Ngãi | O12: Thôn ĐăkTrăm, xã Kon Đào, Quảng Ngãi | P12: Thôn ĐăkTrăm, xã Kon Đào, Quảng Ngãi | X12: =IF(D12="","",IF(YEAR(TODAY())-D12<15,"Không đủ tuổi theo học",IF(AND(E12="Nam",YEAR(TODAY())-D12>60),"Quá tuổi theo học",IF(AND(E12="Nữ",YEAR(TODAY())-D12>55),"Quá tuổi theo học","Đảm bảo")))) | Y12: =IF(C12="","",IF(OR(LEFT(C12,1)="Y",LEFT(C12,1)="A"),"",IF(L12<>"Đối tượng lao động nông thôn khác","Cần hồ sơ chứng minh nhóm đối tượng",""))) | AA12: =IF(OR(D12="",'KHÓA HỌC'!$D$8=""),"",DATEDIF(D12,'KHÓA HỌC'!$D$8,"y")) | AB12: =IF(C12<>"",AND(E12="Nữ",L12="Người dân tộc thiểu số"),"") | AC12: =IF(C12<>"",L12="Người dân tộc thiểu số","") | AD12: =IF(C12<>"",'THỐNG KÊ'!$E$5-'Thông tin HV'!D12<31,"") | AE12: =IF(C12<>"",AND(AC12,AD12),"") | AF12: =IF(C12<>"",(K12>=9),"") | AG12: =IF(C12<>"",AND(AF12,E12="Nữ"),"") | AH12: =IF(C12<>"",AND(AF12,AC12),"") | AI12: =IF(C12<>"",'THỐNG KÊ'!$E$5-'Thông tin HV'!D12<26,"") | AJ12: =IF(C12<>"",AND(AI12,E12="Nữ"),"") | AK12: =IF(C12<>"",AND(AI12,AC12),"") | AL12: =IF(C12<>"",AND('THỐNG KÊ'!$E$5-'Thông tin HV'!D12>=26,'THỐNG KÊ'!$E$5-'Thông tin HV'!D12<=45),"") | AM12: =IF(C12<>"",AND(AL12,E12="Nữ"),"") | AN12: =IF(C12<>"",AND(AL12,AC12),"") | AO12: =IF(C12<>"",'THỐNG KÊ'!$E$5-'Thông tin HV'!D12>45,"") | AP12: =IF(C12<>"",AND(AO12,E12="Nữ"),"") | AQ12: =IF(C12<>"",AND(AO12,AC12),"") | AR12: =IF(C12<>"",AND(Z12="x",E12="Nữ"),"") | AS12: =IF(C12<>"",AND(Z12="x",E12="Nữ",L12="Người dân tộc thiểu số"),"") | AT12: =IF(C12<>"",AND(Z12="x",L12="Người dân tộc thiểu số"),"") | AU12: =IF(C12<>"",AND(Z12="x",'THỐNG KÊ'!$E$5-'Thông tin HV'!D12<31),"") | AV12: =IF(C12<>"",AND(Z12="x",AC12,AD12),"") | AW12: =IF(C12<>"",AND(K12>=9,Z12="x"),"") | AX12: =IF(C12<>"",AND(Z12="x",AI12,E12="Nữ"),"") | AY12: =IF(C12<>"",AND(Z12="x",AF12,AC12),"") | AZ12: =IF(C12<>"",AND(Z12="x",'THỐNG KÊ'!$E$5-'Thông tin HV'!D12<26),"") | BA12: =IF(C12<>"",AND(Z12="x",AI12,E12="Nữ"),"") | BB12: =IF(C12<>"",AND(Z12="x",AI12,AC12),"") | BC12: =IF(C12<>"",AND(Z12="x",'THỐNG KÊ'!$E$5-'Thông tin HV'!D12>=26,'THỐNG KÊ'!$E$5-'Thông tin HV'!D12<=45),"") | BD12: =IF(C12<>"",AND(Z12="x",AL12,E12="Nữ"),"") | BE12: =IF(C12<>"",AND(Z12="x",AL12,AC12),"") | BF12: =IF(C12<>"",AND(Z12="x",'THỐNG KÊ'!$E$5-'Thông tin HV'!D12>45),"") | BG12: =IF(C12<>"",AND(Z12="x",AO12,E12="Nữ"),"") | BH12: =IF(C12<>"",AND(Z12="x",AO12,AC12),"")
A13: 10 | C13: A Bếch | D13: 30386 | E13: Nam | G13: Xê Đăng | I13: =IF(AA13="","",IF(AA13<=30,"X","")) | J13: =IF(AND(I13="X",G13<>"Kinh"),"X","") | K13: 9 | L13: Người dân tộc thiểu số | M13: =VLOOKUP(L13,IDs!$H$3:$I$12,2,0) | N13: Thôn ĐăkTrăm, xã Kon Đào, Quảng Ngãi | O13: Thôn ĐăkTrăm, xã Kon Đào, Quảng Ngãi | P13: Thôn ĐăkTrăm, xã Kon Đào, Quảng Ngãi | X13: =IF(D13="","",IF(YEAR(TODAY())-D13<15,"Không đủ tuổi theo học",IF(AND(E13="Nam",YEAR(TODAY())-D13>60),"Quá tuổi theo học",IF(AND(E13="Nữ",YEAR(TODAY())-D13>55),"Quá tuổi theo học","Đảm bảo")))) | Y13: =IF(C13="","",IF(OR(LEFT(C13,1)="Y",LEFT(C13,1)="A"),"",IF(L13<>"Đối tượng lao động nông thôn khác","Cần hồ sơ chứng minh nhóm đối tượng",""))) | AA13: =IF(OR(D13="",'KHÓA HỌC'!$D$8=""),"",DATEDIF(D13,'KHÓA HỌC'!$D$8,"y")) | AB13: =IF(C13<>"",AND(E13="Nữ",L13="Người dân tộc thiểu số"),"") | AC13: =IF(C13<>"",L13="Người dân tộc thiểu số","") | AD13: =IF(C13<>"",'THỐNG KÊ'!$E$5-'Thông tin HV'!D13<31,"") | AE13: =IF(C13<>"",AND(AC13,AD13),"") | AF13: =IF(C13<>"",(K13>=9),"") | AG13: =IF(C13<>"",AND(AF13,E13="Nữ"),"") | AH13: =IF(C13<>"",AND(AF13,AC13),"") | AI13: =IF(C13<>"",'THỐNG KÊ'!$E$5-'Thông tin HV'!D13<26,"") | AJ13: =IF(C13<>"",AND(AI13,E13="Nữ"),"") | AK13: =IF(C13<>"",AND(AI13,AC13),"") | AL13: =IF(C13<>"",AND('THỐNG KÊ'!$E$5-'Thông tin HV'!D13>=26,'THỐNG KÊ'!$E$5-'Thông tin HV'!D13<=45),"") | AM13: =IF(C13<>"",AND(AL13,E13="Nữ"),"") | AN13: =IF(C13<>"",AND(AL13,AC13),"") | AO13: =IF(C13<>"",'THỐNG KÊ'!$E$5-'Thông tin HV'!D13>45,"") | AP13: =IF(C13<>"",AND(AO13,E13="Nữ"),"") | AQ13: =IF(C13<>"",AND(AO13,AC13),"") | AR13: =IF(C13<>"",AND(Z13="x",E13="Nữ"),"") | AS13: =IF(C13<>"",AND(Z13="x",E13="Nữ",L13="Người dân tộc thiểu số"),"") | AT13: =IF(C13<>"",AND(Z13="x",L13="Người dân tộc thiểu số"),"") | AU13: =IF(C13<>"",AND(Z13="x",'THỐNG KÊ'!$E$5-'Thông tin HV'!D13<31),"") | AV13: =IF(C13<>"",AND(Z13="x",AC13,AD13),"") | AW13: =IF(C13<>"",AND(K13>=9,Z13="x"),"") | AX13: =IF(C13<>"",AND(Z13="x",AI13,E13="Nữ"),"") | AY13: =IF(C13<>"",AND(Z13="x",AF13,AC13),"") | AZ13: =IF(C13<>"",AND(Z13="x",'THỐNG KÊ'!$E$5-'Thông tin HV'!D13<26),"") | BA13: =IF(C13<>"",AND(Z13="x",AI13,E13="Nữ"),"") | BB13: =IF(C13<>"",AND(Z13="x",AI13,AC13),"") | BC13: =IF(C13<>"",AND(Z13="x",'THỐNG KÊ'!$E$5-'Thông tin HV'!D13>=26,'THỐNG KÊ'!$E$5-'Thông tin HV'!D13<=45),"") | BD13: =IF(C13<>"",AND(Z13="x",AL13,E13="Nữ"),"") | BE13: =IF(C13<>"",AND(Z13="x",AL13,AC13),"") | BF13: =IF(C13<>"",AND(Z13="x",'THỐNG KÊ'!$E$5-'Thông tin HV'!D13>45),"") | BG13: =IF(C13<>"",AND(Z13="x",AO13,E13="Nữ"),"") | BH13: =IF(C13<>"",AND(Z13="x",AO13,AC13),"")
A14: 11 | C14: A Đông | D14: 30386 | E14: Nam | G14: Xê Đăng | I14: =IF(AA14="","",IF(AA14<=30,"X","")) | J14: =IF(AND(I14="X",G14<>"Kinh"),"X","") | K14: 8 | L14: Người dân tộc thiểu số | M14: =VLOOKUP(L14,IDs!$H$3:$I$12,2,0) | N14: Thôn ĐăkTrăm, xã Kon Đào, Quảng Ngãi | O14: Thôn ĐăkTrăm, xã Kon Đào, Quảng Ngãi | P14: Thôn ĐăkTrăm, xã Kon Đào, Quảng Ngãi | X14: =IF(D14="","",IF(YEAR(TODAY())-D14<15,"Không đủ tuổi theo học",IF(AND(E14="Nam",YEAR(TODAY())-D14>60),"Quá tuổi theo học",IF(AND(E14="Nữ",YEAR(TODAY())-D14>55),"Quá tuổi theo học","Đảm bảo")))) | Y14: =IF(C14="","",IF(OR(LEFT(C14,1)="Y",LEFT(C14,1)="A"),"",IF(L14<>"Đối tượng lao động nông thôn khác","Cần hồ sơ chứng minh nhóm đối tượng",""))) | AA14: =IF(OR(D14="",'KHÓA HỌC'!$D$8=""),"",DATEDIF(D14,'KHÓA HỌC'!$D$8,"y")) | AB14: =IF(C14<>"",AND(E14="Nữ",L14="Người dân tộc thiểu số"),"") | AC14: =IF(C14<>"",L14="Người dân tộc thiểu số","") | AD14: =IF(C14<>"",'THỐNG KÊ'!$E$5-'Thông tin HV'!D14<31,"") | AE14: =IF(C14<>"",AND(AC14,AD14),"") | AF14: =IF(C14<>"",(K14>=9),"") | AG14: =IF(C14<>"",AND(AF14,E14="Nữ"),"") | AH14: =IF(C14<>"",AND(AF14,AC14),"") | AI14: =IF(C14<>"",'THỐNG KÊ'!$E$5-'Thông tin HV'!D14<26,"") | AJ14: =IF(C14<>"",AND(AI14,E14="Nữ"),"") | AK14: =IF(C14<>"",AND(AI14,AC14),"") | AL14: =IF(C14<>"",AND('THỐNG KÊ'!$E$5-'Thông tin HV'!D14>=26,'THỐNG KÊ'!$E$5-'Thông tin HV'!D14<=45),"") | AM14: =IF(C14<>"",AND(AL14,E14="Nữ"),"") | AN14: =IF(C14<>"",AND(AL14,AC14),"") | AO14: =IF(C14<>"",'THỐNG KÊ'!$E$5-'Thông tin HV'!D14>45,"") | AP14: =IF(C14<>"",AND(AO14,E14="Nữ"),"") | AQ14: =IF(C14<>"",AND(AO14,AC14),"") | AR14: =IF(C14<>"",AND(Z14="x",E14="Nữ"),"") | AS14: =IF(C14<>"",AND(Z14="x",E14="Nữ",L14="Người dân tộc thiểu số"),"") | AT14: =IF(C14<>"",AND(Z14="x",L14="Người dân tộc thiểu số"),"") | AU14: =IF(C14<>"",AND(Z14="x",'THỐNG KÊ'!$E$5-'Thông tin HV'!D14<31),"") | AV14: =IF(C14<>"",AND(Z14="x",AC14,AD14),"") | AW14: =IF(C14<>"",AND(K14>=9,Z14="x"),"") | AX14: =IF(C14<>"",AND(Z14="x",AI14,E14="Nữ"),"") | AY14: =IF(C14<>"",AND(Z14="x",AF14,AC14),"") | AZ14: =IF(C14<>"",AND(Z14="x",'THỐNG KÊ'!$E$5-'Thông tin HV'!D14<26),"") | BA14: =IF(C14<>"",AND(Z14="x",AI14,E14="Nữ"),"") | BB14: =IF(C14<>"",AND(Z14="x",AI14,AC14),"") | BC14: =IF(C14<>"",AND(Z14="x",'THỐNG KÊ'!$E$5-'Thông tin HV'!D14>=26,'THỐNG KÊ'!$E$5-'Thông tin HV'!D14<=45),"") | BD14: =IF(C14<>"",AND(Z14="x",AL14,E14="Nữ"),"") | BE14: =IF(C14<>"",AND(Z14="x",AL14,AC14),"") | BF14: =IF(C14<>"",AND(Z14="x",'THỐNG KÊ'!$E$5-'Thông tin HV'!D14>45),"") | BG14: =IF(C14<>"",AND(Z14="x",AO14,E14="Nữ"),"") | BH14: =IF(C14<>"",AND(Z14="x",AO14,AC14),"")
A15: 12 | C15: A Lung | D15: 30386 | E15: Nam | G15: Xê Đăng | I15: =IF(AA15="","",IF(AA15<=30,"X","")) | J15: =IF(AND(I15="X",G15<>"Kinh"),"X","") | K15: 9 | L15: Người dân tộc thiểu số | M15: =VLOOKUP(L15,IDs!$H$3:$I$12,2,0) | N15: Thôn ĐăkTrăm, xã Kon Đào, Quảng Ngãi | O15: Thôn ĐăkTrăm, xã Kon Đào, Quảng Ngãi | P15: Thôn ĐăkTrăm, xã Kon Đào, Quảng Ngãi | X15: =IF(D15="","",IF(YEAR(TODAY())-D15<15,"Không đủ tuổi theo học",IF(AND(E15="Nam",YEAR(TODAY())-D15>60),"Quá tuổi theo học",IF(AND(E15="Nữ",YEAR(TODAY())-D15>55),"Quá tuổi theo học","Đảm bảo")))) | Y15: =IF(C15="","",IF(OR(LEFT(C15,1)="Y",LEFT(C15,1)="A"),"",IF(L15<>"Đối tượng lao động nông thôn khác","Cần hồ sơ chứng minh nhóm đối tượng",""))) | AA15: =IF(OR(D15="",'KHÓA HỌC'!$D$8=""),"",DATEDIF(D15,'KHÓA HỌC'!$D$8,"y")) | AB15: =IF(C15<>"",AND(E15="Nữ",L15="Người dân tộc thiểu số"),"") | AC15: =IF(C15<>"",L15="Người dân tộc thiểu số","") | AD15: =IF(C15<>"",'THỐNG KÊ'!$E$5-'Thông tin HV'!D15<31,"") | AE15: =IF(C15<>"",AND(AC15,AD15),"") | AF15: =IF(C15<>"",(K15>=9),"") | AG15: =IF(C15<>"",AND(AF15,E15="Nữ"),"") | AH15: =IF(C15<>"",AND(AF15,AC15),"") | AI15: =IF(C15<>"",'THỐNG KÊ'!$E$5-'Thông tin HV'!D15<26,"") | AJ15: =IF(C15<>"",AND(AI15,E15="Nữ"),"") | AK15: =IF(C15<>"",AND(AI15,AC15),"") | AL15: =IF(C15<>"",AND('THỐNG KÊ'!$E$5-'Thông tin HV'!D15>=26,'THỐNG KÊ'!$E$5-'Thông tin HV'!D15<=45),"") | AM15: =IF(C15<>"",AND(AL15,E15="Nữ"),"") | AN15: =IF(C15<>"",AND(AL15,AC15),"") | AO15: =IF(C15<>"",'THỐNG KÊ'!$E$5-'Thông tin HV'!D15>45,"") | AP15: =IF(C15<>"",AND(AO15,E15="Nữ"),"") | AQ15: =IF(C15<>"",AND(AO15,AC15),"") | AR15: =IF(C15<>"",AND(Z15="x",E15="Nữ"),"") | AS15: =IF(C15<>"",AND(Z15="x",E15="Nữ",L15="Người dân tộc thiểu số"),"") | AT15: =IF(C15<>"",AND(Z15="x",L15="Người dân tộc thiểu số"),"") | AU15: =IF(C15<>"",AND(Z15="x",'THỐNG KÊ'!$E$5-'Thông tin HV'!D15<31),"") | AV15: =IF(C15<>"",AND(Z15="x",AC15,AD15),"") | AW15: =IF(C15<>"",AND(K15>=9,Z15="x"),"") | AX15: =IF(C15<>"",AND(Z15="x",AI15,E15="Nữ"),"") | AY15: =IF(C15<>"",AND(Z15="x",AF15,AC15),"") | AZ15: =IF(C15<>"",AND(Z15="x",'THỐNG KÊ'!$E$5-'Thông tin HV'!D15<26),"") | BA15: =IF(C15<>"",AND(Z15="x",AI15,E15="Nữ"),"") | BB15: =IF(C15<>"",AND(Z15="x",AI15,AC15),"") | BC15: =IF(C15<>"",AND(Z15="x",'THỐNG KÊ'!$E$5-'Thông tin HV'!D15>=26,'THỐNG KÊ'!$E$5-'Thông tin HV'!D15<=45),"") | BD15: =IF(C15<>"",AND(Z15="x",AL15,E15="Nữ"),"") | BE15: =IF(C15<>"",AND(Z15="x",AL15,AC15),"") | BF15: =IF(C15<>"",AND(Z15="x",'THỐNG KÊ'!$E$5-'Thông tin HV'!D15>45),"") | BG15: =IF(C15<>"",AND(Z15="x",AO15,E15="Nữ"),"") | BH15: =IF(C15<>"",AND(Z15="x",AO15,AC15),"")
... A33: 30 | C33: Y Khiêm | D33: 30386 | E33: Nữ | G33: Xê Đăng | I33: =IF(AA33="","",IF(AA33<=30,"X","")) | J33: =IF(AND(I33="X",G33<>"Kinh"),"X","") | K33: 5 | L33: Người dân tộc thiểu số | M33: =VLOOKUP(L33,IDs!$H$3:$I$12,2,0) | N33: Thôn ĐăkTrăm, xã Kon Đào, Quảng Ngãi | O33: Thôn ĐăkTrăm, xã Kon Đào, Quảng Ngãi | P33: Thôn ĐăkTrăm, xã Kon Đào, Quảng Ngãi | X33: =IF(D33="","",IF(YEAR(TODAY())-D33<15,"Không đủ tuổi theo học",IF(AND(E33="Nam",YEAR(TODAY())-D33>60),"Quá tuổi theo học",IF(AND(E33="Nữ",YEAR(TODAY())-D33>55),"Quá tuổi theo học","Đảm bảo")))) | Y33: =IF(C33="","",IF(OR(LEFT(C33,1)="Y",LEFT(C33,1)="A"),"",IF(L33<>"Đối tượng lao động nông thôn khác","Cần hồ sơ chứng minh nhóm đối tượng",""))) | AA33: =IF(OR(D33="",'KHÓA HỌC'!$D$8=""),"",DATEDIF(D33,'KHÓA HỌC'!$D$8,"y")) | AB33: =IF(C33<>"",AND(E33="Nữ",L33="Người dân tộc thiểu số"),"") | AC33: =IF(C33<>"",L33="Người dân tộc thiểu số","") | AD33: =IF(C33<>"",'THỐNG KÊ'!$E$5-'Thông tin HV'!D33<31,"") | AE33: =IF(C33<>"",AND(AC33,AD33),"") | AF33: =IF(C33<>"",(K33>=9),"") | AG33: =IF(C33<>"",AND(AF33,E33="Nữ"),"") | AH33: =IF(C33<>"",AND(AF33,AC33),"") | AI33: =IF(C33<>"",'THỐNG KÊ'!$E$5-'Thông tin HV'!D33<26,"") | AJ33: =IF(C33<>"",AND(AI33,E33="Nữ"),"") | AK33: =IF(C33<>"",AND(AI33,AC33),"") | AL33: =IF(C33<>"",AND('THỐNG KÊ'!$E$5-'Thông tin HV'!D33>=26,'THỐNG KÊ'!$E$5-'Thông tin HV'!D33<=45),"") | AM33: =IF(C33<>"",AND(AL33,E33="Nữ"),"") | AN33: =IF(C33<>"",AND(AL33,AC33),"") | AO33: =IF(C33<>"",'THỐNG KÊ'!$E$5-'Thông tin HV'!D33>45,"") | AP33: =IF(C33<>"",AND(AO33,E33="Nữ"),"") | AQ33: =IF(C33<>"",AND(AO33,AC33),"") | AR33: =IF(C33<>"",AND(Z33="x",E33="Nữ"),"") | AS33: =IF(C33<>"",AND(Z33="x",E33="Nữ",L33="Người dân tộc thiểu số"),"") | AT33: =IF(C33<>"",AND(Z33="x",L33="Người dân tộc thiểu số"),"") | AU33: =IF(C33<>"",AND(Z33="x",'THỐNG KÊ'!$E$5-'Thông tin HV'!D33<31),"") | AV33: =IF(C33<>"",AND(Z33="x",AC33,AD33),"") | AW33: =IF(C33<>"",AND(K33>=9,Z33="x"),"") | AX33: =IF(C33<>"",AND(Z33="x",AI33,E33="Nữ"),"") | AY33: =IF(C33<>"",AND(Z33="x",AF33,AC33),"") | AZ33: =IF(C33<>"",AND(Z33="x",'THỐNG KÊ'!$E$5-'Thông tin HV'!D33<26),"") | BA33: =IF(C33<>"",AND(Z33="x",AI33,E33="Nữ"),"") | BB33: =IF(C33<>"",AND(Z33="x",AI33,AC33),"") | BC33: =IF(C33<>"",AND(Z33="x",'THỐNG KÊ'!$E$5-'Thông tin HV'!D33>=26,'THỐNG KÊ'!$E$5-'Thông tin HV'!D33<=45),"") | BD33: =IF(C33<>"",AND(Z33="x",AL33,E33="Nữ"),"") | BE33: =IF(C33<>"",AND(Z33="x",AL33,AC33),"") | BF33: =IF(C33<>"",AND(Z33="x",'THỐNG KÊ'!$E$5-'Thông tin HV'!D33>45),"") | BG33: =IF(C33<>"",AND(Z33="x",AO33,E33="Nữ"),"") | BH33: =IF(C33<>"",AND(Z33="x",AO33,AC33),"")
A34: 31 | C34: Y Khuy | D34: 30386 | E34: Nữ | G34: Xê Đăng | I34: =IF(AA34="","",IF(AA34<=30,"X","")) | J34: =IF(AND(I34="X",G34<>"Kinh"),"X","") | K34: 9 | L34: Người dân tộc thiểu số | M34: =VLOOKUP(L34,IDs!$H$3:$I$12,2,0) | N34: Thôn ĐăkTrăm, xã Kon Đào, Quảng Ngãi | O34: Thôn ĐăkTrăm, xã Kon Đào, Quảng Ngãi | P34: Thôn ĐăkTrăm, xã Kon Đào, Quảng Ngãi | X34: =IF(D34="","",IF(YEAR(TODAY())-D34<15,"Không đủ tuổi theo học",IF(AND(E34="Nam",YEAR(TODAY())-D34>60),"Quá tuổi theo học",IF(AND(E34="Nữ",YEAR(TODAY())-D34>55),"Quá tuổi theo học","Đảm bảo")))) | AA34: =IF(OR(D34="",'KHÓA HỌC'!$D$8=""),"",DATEDIF(D34,'KHÓA HỌC'!$D$8,"y")) | AF34: =IF(C34<>"",(K34>=9),"") | AG34: =IF(C34<>"",AND(AF34,E34="Nữ"),"")
A35: 32 | C35: Y Lúi | D35: 30386 | E35: Nữ | G35: Xê Đăng | I35: =IF(AA35="","",IF(AA35<=30,"X","")) | J35: =IF(AND(I35="X",G35<>"Kinh"),"X","") | K35: 4 | L35: Người dân tộc thiểu số | M35: =VLOOKUP(L35,IDs!$H$3:$I$12,2,0) | N35: Thôn ĐăkTrăm, xã Kon Đào, Quảng Ngãi | O35: Thôn ĐăkTrăm, xã Kon Đào, Quảng Ngãi | P35: Thôn ĐăkTrăm, xã Kon Đào, Quảng Ngãi | X35: =IF(D35="","",IF(YEAR(TODAY())-D35<15,"Không đủ tuổi theo học",IF(AND(E35="Nam",YEAR(TODAY())-D35>60),"Quá tuổi theo học",IF(AND(E35="Nữ",YEAR(TODAY())-D35>55),"Quá tuổi theo học","Đảm bảo")))) | AA35: =IF(OR(D35="",'KHÓA HỌC'!$D$8=""),"",DATEDIF(D35,'KHÓA HỌC'!$D$8,"y")) | AF35: =IF(C35<>"",(K35>=9),"") | AG35: =IF(C35<>"",AND(AF35,E35="Nữ"),"")
A36: 33 | C36: Y Loan | D36: 30386 | E36: Nữ | G36: Xê Đăng | I36: =IF(AA36="","",IF(AA36<=30,"X","")) | J36: =IF(AND(I36="X",G36<>"Kinh"),"X","") | K36: 9 | L36: Người dân tộc thiểu số | M36: =VLOOKUP(L36,IDs!$H$3:$I$12,2,0) | N36: Thôn ĐăkTrăm, xã Kon Đào, Quảng Ngãi | O36: Thôn ĐăkTrăm, xã Kon Đào, Quảng Ngãi | P36: Thôn ĐăkTrăm, xã Kon Đào, Quảng Ngãi | X36: =IF(D36="","",IF(YEAR(TODAY())-D36<15,"Không đủ tuổi theo học",IF(AND(E36="Nam",YEAR(TODAY())-D36>60),"Quá tuổi theo học",IF(AND(E36="Nữ",YEAR(TODAY())-D36>55),"Quá tuổi theo học","Đảm bảo")))) | AA36: =IF(OR(D36="",'KHÓA HỌC'!$D$8=""),"",DATEDIF(D36,'KHÓA HỌC'!$D$8,"y")) | AF36: =IF(C36<>"",(K36>=9),"") | AG36: =IF(C36<>"",AND(AF36,E36="Nữ"),"")
AA37: =IF(OR(D37="",'KHÓA HỌC'!$D$8=""),"",DATEDIF(D37,'KHÓA HỌC'!$D$8,"y"))
AA38: =IF(OR(D38="",'KHÓA HỌC'!$D$8=""),"",DATEDIF(D38,'KHÓA HỌC'!$D$8,"y"))
AA39: =IF(OR(D39="",'KHÓA HỌC'!$D$8=""),"",DATEDIF(D39,'KHÓA HỌC'!$D$8,"y")) | AB39: =COUNTIF(AB4:AB38,"TRUE") | AC39: =COUNTIF(AC4:AC38,"TRUE") | AD39: =COUNTIF(AD4:AD38,"TRUE") | AE39: =COUNTIF(AE4:AE38,"TRUE") | AF39: =COUNTIF(AF4:AF38,"TRUE") | AG39: =COUNTIF(AG4:AG38,"TRUE") | AH39: =COUNTIF(AH4:AH38,"TRUE") | AI39: =COUNTIF(AI4:AI38,"TRUE") | ... BH39: =COUNTIF(BH4:BH38,"TRUE")

Sheet DSTN-Xã
B1: UBND XÃ………………. | K1: CỘNG HÒA XÃ HỘI CHỦ NGHĨA VIỆT NAM
B2: PHÒNG……………………….. | K2: Độc lập - Tự do - Hạnh phúc
A5: DANH SÁCH TRÍCH NGANG HỌC VIÊN
A6: ="Tham gia lớp Đào tạo Nghề: "&UPPER('KHÓA HỌC'!D5)&"; Khóa: "&'KHÓA HỌC'!D3&"; Năm "&'KHÓA HỌC'!D4
A7: ="Địa điểm mở lớp: "&'KHÓA HỌC'!D16&", "&'KHÓA HỌC'!D17&", "&'KHÓA HỌC'!D18
A9: Số TT | B9: Họ và tên | D9: Ngày, tháng, năm sinh | E9: Giới tính | F9: Dân tộc | G9: Thanh niên | H9: Thanh niên DTTS | I9: Trình độ văn hóa | J9: Nhóm đối tượng | K9: Nguyên quán | L9: Nơi cư trú | M9: Ghi chú
A10: 1 | B10: =PROPER(TRIM(LEFT(TRIM('Thông tin HV'!C4),LEN(TRIM('Thông tin HV'!C4))-LEN(C10)))) | C10: =PROPER(TRIM(RIGHT(SUBSTITUTE(TRIM('Thông tin HV'!C4)," ",REPT(" ",100)),100))) | D10: ='Thông tin HV'!D4 | E10: ='Thông tin HV'!E4 | F10: ='Thông tin HV'!G4 | G10: ='Thông tin HV'!I4 | H10: ='Thông tin HV'!J4 | I10: ='Thông tin HV'!K4&"/12" | J10: 3 | K10: ='Thông tin HV'!O4 | L10: ='Thông tin HV'!P4
A11: 2 | B11: =PROPER(TRIM(LEFT(TRIM('Thông tin HV'!C5),LEN(TRIM('Thông tin HV'!C5))-LEN(C11)))) | C11: =PROPER(TRIM(RIGHT(SUBSTITUTE(TRIM('Thông tin HV'!C5)," ",REPT(" ",100)),100))) | D11: ='Thông tin HV'!D5 | E11: Nam | F11: Xê Đăng | I11: ='Thông tin HV'!K5&"/12" | J11: 3 | K11: ='Thông tin HV'!O5 | L11: ='Thông tin HV'!P5
A12: 3 | B12: =PROPER(TRIM(LEFT(TRIM('Thông tin HV'!C6),LEN(TRIM('Thông tin HV'!C6))-LEN(C12)))) | C12: =PROPER(TRIM(RIGHT(SUBSTITUTE(TRIM('Thông tin HV'!C6)," ",REPT(" ",100)),100))) | D12: ='Thông tin HV'!D6 | E12: Nam | F12: Xê Đăng | G12: x | H12: x | I12: ='Thông tin HV'!K6&"/12" | J12: 3 | K12: ='Thông tin HV'!O6 | L12: ='Thông tin HV'!P6
A13: 4 | B13: =PROPER(TRIM(LEFT(TRIM('Thông tin HV'!C7),LEN(TRIM('Thông tin HV'!C7))-LEN(C13)))) | C13: =PROPER(TRIM(RIGHT(SUBSTITUTE(TRIM('Thông tin HV'!C7)," ",REPT(" ",100)),100))) | D13: ='Thông tin HV'!D7 | E13: Nam | F13: Xê Đăng | I13: ='Thông tin HV'!K7&"/12" | J13: 3 | K13: ='Thông tin HV'!O7 | L13: ='Thông tin HV'!P7
A14: 5 | B14: =PROPER(TRIM(LEFT(TRIM('Thông tin HV'!C8),LEN(TRIM('Thông tin HV'!C8))-LEN(C14)))) | C14: =PROPER(TRIM(RIGHT(SUBSTITUTE(TRIM('Thông tin HV'!C8)," ",REPT(" ",100)),100))) | D14: ='Thông tin HV'!D8 | E14: Nam | F14: Xê Đăng | G14: x | H14: x | I14: ='Thông tin HV'!K8&"/12" | J14: 3 | K14: ='Thông tin HV'!O8 | L14: ='Thông tin HV'!P8
A15: 6 | B15: =PROPER(TRIM(LEFT(TRIM('Thông tin HV'!C9),LEN(TRIM('Thông tin HV'!C9))-LEN(C15)))) | C15: =PROPER(TRIM(RIGHT(SUBSTITUTE(TRIM('Thông tin HV'!C9)," ",REPT(" ",100)),100))) | D15: ='Thông tin HV'!D9 | E15: Nam | F15: Xê Đăng | I15: ='Thông tin HV'!K9&"/12" | J15: 3 | K15: ='Thông tin HV'!O9 | L15: ='Thông tin HV'!P9
A16: 7 | B16: =PROPER(TRIM(LEFT(TRIM('Thông tin HV'!C10),LEN(TRIM('Thông tin HV'!C10))-LEN(C16)))) | C16: =PROPER(TRIM(RIGHT(SUBSTITUTE(TRIM('Thông tin HV'!C10)," ",REPT(" ",100)),100))) | D16: ='Thông tin HV'!D10 | E16: Nam | F16: Xê Đăng | G16: x | H16: x | I16: ='Thông tin HV'!K10&"/12" | J16: 3 | K16: ='Thông tin HV'!O10 | L16: ='Thông tin HV'!P10
A17: 8 | B17: =PROPER(TRIM(LEFT(TRIM('Thông tin HV'!C11),LEN(TRIM('Thông tin HV'!C11))-LEN(C17)))) | C17: =PROPER(TRIM(RIGHT(SUBSTITUTE(TRIM('Thông tin HV'!C11)," ",REPT(" ",100)),100))) | D17: ='Thông tin HV'!D11 | E17: Nam | F17: Xê Đăng | I17: ='Thông tin HV'!K11&"/12" | J17: 3 | K17: ='Thông tin HV'!O11 | L17: ='Thông tin HV'!P11
A18: 9 | B18: =PROPER(TRIM(LEFT(TRIM('Thông tin HV'!C12),LEN(TRIM('Thông tin HV'!C12))-LEN(C18)))) | C18: =PROPER(TRIM(RIGHT(SUBSTITUTE(TRIM('Thông tin HV'!C12)," ",REPT(" ",100)),100))) | D18: ='Thông tin HV'!D12 | E18: Nam | F18: Xê Đăng | G18: x | H18: x | I18: ='Thông tin HV'!K12&"/12" | J18: 3 | K18: ='Thông tin HV'!O12 | L18: ='Thông tin HV'!P12
A19: 10 | B19: =PROPER(TRIM(LEFT(TRIM('Thông tin HV'!C13),LEN(TRIM('Thông tin HV'!C13))-LEN(C19)))) | C19: =PROPER(TRIM(RIGHT(SUBSTITUTE(TRIM('Thông tin HV'!C13)," ",REPT(" ",100)),100))) | D19: ='Thông tin HV'!D13 | E19: Nam | F19: Xê Đăng | G19: x | H19: x | I19: ='Thông tin HV'!K13&"/12" | J19: 3 | K19: ='Thông tin HV'!O13 | L19: ='Thông tin HV'!P13
A20: 11 | B20: =PROPER(TRIM(LEFT(TRIM('Thông tin HV'!C14),LEN(TRIM('Thông tin HV'!C14))-LEN(C20)))) | C20: =PROPER(TRIM(RIGHT(SUBSTITUTE(TRIM('Thông tin HV'!C14)," ",REPT(" ",100)),100))) | D20: ='Thông tin HV'!D14 | E20: Nam | F20: Xê Đăng | G20: x | H20: x | I20: ='Thông tin HV'!K14&"/12" | J20: 3 | K20: ='Thông tin HV'!O14 | L20: ='Thông tin HV'!P14
A21: 12 | B21: =PROPER(TRIM(LEFT(TRIM('Thông tin HV'!C15),LEN(TRIM('Thông tin HV'!C15))-LEN(C21)))) | C21: =PROPER(TRIM(RIGHT(SUBSTITUTE(TRIM('Thông tin HV'!C15)," ",REPT(" ",100)),100))) | D21: ='Thông tin HV'!D15 | E21: Nam | F21: Xê Đăng | I21: ='Thông tin HV'!K15&"/12" | J21: 3 | K21: ='Thông tin HV'!O15 | L21: ='Thông tin HV'!P15
A22: 13 | B22: =PROPER(TRIM(LEFT(TRIM('Thông tin HV'!C16),LEN(TRIM('Thông tin HV'!C16))-LEN(C22)))) | C22: =PROPER(TRIM(RIGHT(SUBSTITUTE(TRIM('Thông tin HV'!C16)," ",REPT(" ",100)),100))) | D22: ='Thông tin HV'!D16 | E22: Nam | F22: Xê Đăng | G22: x | H22: x | I22: ='Thông tin HV'!K16&"/12" | J22: 3 | K22: ='Thông tin HV'!O16 | L22: ='Thông tin HV'!P16
A23: 14 | B23: =PROPER(TRIM(LEFT(TRIM('Thông tin HV'!C17),LEN(TRIM('Thông tin HV'!C17))-LEN(C23)))) | C23: =PROPER(TRIM(RIGHT(SUBSTITUTE(TRIM('Thông tin HV'!C17)," ",REPT(" ",100)),100))) | D23: ='Thông tin HV'!D17 | E23: Nam | F23: Xê Đăng | G23: x | H23: x | I23: ='Thông tin HV'!K17&"/12" | J23: 3 | K23: ='Thông tin HV'!O17 | L23: ='Thông tin HV'!P17
A24: 15 | B24: =PROPER(TRIM(LEFT(TRIM('Thông tin HV'!C18),LEN(TRIM('Thông tin HV'!C18))-LEN(C24)))) | C24: =PROPER(TRIM(RIGHT(SUBSTITUTE(TRIM('Thông tin HV'!C18)," ",REPT(" ",100)),100))) | D24: ='Thông tin HV'!D18 | E24: Nam | F24: Xê Đăng | I24: ='Thông tin HV'!K18&"/12" | J24: 3 | K24: ='Thông tin HV'!O18 | L24: ='Thông tin HV'!P18
A25: 16 | B25: =PROPER(TRIM(LEFT(TRIM('Thông tin HV'!C19),LEN(TRIM('Thông tin HV'!C19))-LEN(C25)))) | C25: =PROPER(TRIM(RIGHT(SUBSTITUTE(TRIM('Thông tin HV'!C19)," ",REPT(" ",100)),100))) | D25: ='Thông tin HV'!D19 | E25: Nam | F25: Xê Đăng | I25: ='Thông tin HV'!K19&"/12" | J25: 3 | K25: ='Thông tin HV'!O19 | L25: ='Thông tin HV'!P19
A26: 17 | B26: =PROPER(TRIM(LEFT(TRIM('Thông tin HV'!C20),LEN(TRIM('Thông tin HV'!C20))-LEN(C26)))) | C26: =PROPER(TRIM(RIGHT(SUBSTITUTE(TRIM('Thông tin HV'!C20)," ",REPT(" ",100)),100))) | D26: ='Thông tin HV'!D20 | E26: Nam | F26: Xê Đăng | I26: ='Thông tin HV'!K20&"/12" | K26: ='Thông tin HV'!O20 | L26: ='Thông tin HV'!P20
A27: 18 | B27: =PROPER(TRIM(LEFT(TRIM('Thông tin HV'!C21),LEN(TRIM('Thông tin HV'!C21))-LEN(C27)))) | C27: =PROPER(TRIM(RIGHT(SUBSTITUTE(TRIM('Thông tin HV'!C21)," ",REPT(" ",100)),100))) | D27: ='Thông tin HV'!D21 | E27: Nam | F27: Xê Đăng | G27: x | H27: x | I27: ='Thông tin HV'!K21&"/12" | J27: 3 | K27: ='Thông tin HV'!O21 | L27: ='Thông tin HV'!P21
A28: 19 | B28: =PROPER(TRIM(LEFT(TRIM('Thông tin HV'!C22),LEN(TRIM('Thông tin HV'!C22))-LEN(C28)))) | C28: =PROPER(TRIM(RIGHT(SUBSTITUTE(TRIM('Thông tin HV'!C22)," ",REPT(" ",100)),100))) | D28: ='Thông tin HV'!D22 | E28: Nam | F28: Xê Đăng | G28: x | H28: x | I28: ='Thông tin HV'!K22&"/12" | J28: 3 | K28: ='Thông tin HV'!O22 | L28: ='Thông tin HV'!P22
A29: 20 | B29: =PROPER(TRIM(LEFT(TRIM('Thông tin HV'!C23),LEN(TRIM('Thông tin HV'!C23))-LEN(C29)))) | C29: =PROPER(TRIM(RIGHT(SUBSTITUTE(TRIM('Thông tin HV'!C23)," ",REPT(" ",100)),100))) | D29: ='Thông tin HV'!D23 | E29: Nam | F29: Xê Đăng | I29: ='Thông tin HV'!K23&"/12" | J29: 3 | K29: ='Thông tin HV'!O23 | L29: ='Thông tin HV'!P23
A30: 21 | B30: =PROPER(TRIM(LEFT(TRIM('Thông tin HV'!C24),LEN(TRIM('Thông tin HV'!C24))-LEN(C30)))) | C30: =PROPER(TRIM(RIGHT(SUBSTITUTE(TRIM('Thông tin HV'!C24)," ",REPT(" ",100)),100))) | D30: ='Thông tin HV'!D24 | E30: Nam | F30: Xê Đăng | G30: x | H30: x | I30: ='Thông tin HV'!K24&"/12" | J30: 3 | K30: ='Thông tin HV'!O24 | L30: ='Thông tin HV'!P24
A31: 22 | B31: =PROPER(TRIM(LEFT(TRIM('Thông tin HV'!C25),LEN(TRIM('Thông tin HV'!C25))-LEN(C31)))) | C31: =PROPER(TRIM(RIGHT(SUBSTITUTE(TRIM('Thông tin HV'!C25)," ",REPT(" ",100)),100))) | D31: ='Thông tin HV'!D25 | E31: Nam | F31: Xê Đăng | I31: ='Thông tin HV'!K25&"/12" | J31: 3 | K31: ='Thông tin HV'!O25 | L31: ='Thông tin HV'!P25
A32: 23 | B32: =PROPER(TRIM(LEFT(TRIM('Thông tin HV'!C26),LEN(TRIM('Thông tin HV'!C26))-LEN(C32)))) | C32: =PROPER(TRIM(RIGHT(SUBSTITUTE(TRIM('Thông tin HV'!C26)," ",REPT(" ",100)),100))) | D32: ='Thông tin HV'!D26 | E32: Nam | F32: Xê Đăng | G32: x | H32: x | I32: ='Thông tin HV'!K26&"/12" | J32: 3 | K32: ='Thông tin HV'!O26 | L32: ='Thông tin HV'!P26
A33: 24 | B33: =PROPER(TRIM(LEFT(TRIM('Thông tin HV'!C27),LEN(TRIM('Thông tin HV'!C27))-LEN(C33)))) | C33: =PROPER(TRIM(RIGHT(SUBSTITUTE(TRIM('Thông tin HV'!C27)," ",REPT(" ",100)),100))) | D33: ='Thông tin HV'!D27 | E33: Nam | F33: Gia Rai | G33: x | H33: x | I33: ='Thông tin HV'!K27&"/12" | J33: 3 | K33: ='Thông tin HV'!O27 | L33: ='Thông tin HV'!P27
A34: 25 | B34: =PROPER(TRIM(LEFT(TRIM('Thông tin HV'!C28),LEN(TRIM('Thông tin HV'!C28))-LEN(C34)))) | C34: =PROPER(TRIM(RIGHT(SUBSTITUTE(TRIM('Thông tin HV'!C28)," ",REPT(" ",100)),100))) | D34: ='Thông tin HV'!D28 | E34: Nam | F34: Xê Đăng | I34: ='Thông tin HV'!K28&"/12" | J34: 3 | K34: ='Thông tin HV'!O28 | L34: ='Thông tin HV'!P28
A35: 26 | B35: =PROPER(TRIM(LEFT(TRIM('Thông tin HV'!C29),LEN(TRIM('Thông tin HV'!C29))-LEN(C35)))) | C35: =PROPER(TRIM(RIGHT(SUBSTITUTE(TRIM('Thông tin HV'!C29)," ",REPT(" ",100)),100))) | D35: ='Thông tin HV'!D29 | E35: Nam | F35: Xê Đăng | G35: x | H35: x | I35: ='Thông tin HV'!K29&"/12" | J35: 3 | K35: ='Thông tin HV'!O29 | L35: ='Thông tin HV'!P29
A36: 27 | B36: =PROPER(TRIM(LEFT(TRIM('Thông tin HV'!C30),LEN(TRIM('Thông tin HV'!C30))-LEN(C36)))) | C36: =PROPER(TRIM(RIGHT(SUBSTITUTE(TRIM('Thông tin HV'!C30)," ",REPT(" ",100)),100))) | D36: ='Thông tin HV'!D30 | E36: Nam | F36: Xê Đăng | I36: ='Thông tin HV'!K30&"/12" | J36: 3 | K36: ='Thông tin HV'!O30 | L36: ='Thông tin HV'!P30
A37: 28 | B37: =PROPER(TRIM(LEFT(TRIM('Thông tin HV'!C31),LEN(TRIM('Thông tin HV'!C31))-LEN(C37)))) | C37: =PROPER(TRIM(RIGHT(SUBSTITUTE(TRIM('Thông tin HV'!C31)," ",REPT(" ",100)),100))) | D37: ='Thông tin HV'!D31 | E37: Nam | F37: Xê Đăng | G37: x | H37: x | I37: ='Thông tin HV'!K31&"/12" | J37: 3 | K37: ='Thông tin HV'!O31 | L37: ='Thông tin HV'!P31
A38: 29 | B38: =PROPER(TRIM(LEFT(TRIM('Thông tin HV'!C32),LEN(TRIM('Thông tin HV'!C32))-LEN(C38)))) | C38: =PROPER(TRIM(RIGHT(SUBSTITUTE(TRIM('Thông tin HV'!C32)," ",REPT(" ",100)),100))) | D38: ='Thông tin HV'!D32 | E38: Nữ | F38: Xê Đăng | G38: x | H38: x | I38: ='Thông tin HV'!K32&"/12" | J38: 3 | K38: ='Thông tin HV'!O32 | L38: ='Thông tin HV'!P32
A39: 30 | B39: =PROPER(TRIM(LEFT(TRIM('Thông tin HV'!C33),LEN(TRIM('Thông tin HV'!C33))-LEN(C39)))) | C39: =PROPER(TRIM(RIGHT(SUBSTITUTE(TRIM('Thông tin HV'!C33)," ",REPT(" ",100)),100))) | D39: ='Thông tin HV'!D33 | E39: Nữ | F39: Xê Đăng | I39: ='Thông tin HV'!K33&"/12" | J39: 3 | K39: ='Thông tin HV'!O33 | L39: ='Thông tin HV'!P33
A40: 31 | B40: =PROPER(TRIM(LEFT(TRIM('Thông tin HV'!C34),LEN(TRIM('Thông tin HV'!C34))-LEN(C40)))) | C40: =PROPER(TRIM(RIGHT(SUBSTITUTE(TRIM('Thông tin HV'!C34)," ",REPT(" ",100)),100))) | D40: ='Thông tin HV'!D34 | E40: Nữ | F40: Xê Đăng | G40: x | H40: x | I40: ='Thông tin HV'!K34&"/12" | J40: 3 | K40: ='Thông tin HV'!O34 | L40: ='Thông tin HV'!P34
A41: 32 | B41: =PROPER(TRIM(LEFT(TRIM('Thông tin HV'!C35),LEN(TRIM('Thông tin HV'!C35))-LEN(C41)))) | C41: =PROPER(TRIM(RIGHT(SUBSTITUTE(TRIM('Thông tin HV'!C35)," ",REPT(" ",100)),100))) | D41: ='Thông tin HV'!D35 | E41: Nữ | F41: Xê Đăng | I41: ='Thông tin HV'!K35&"/12" | J41: 3 | K41: ='Thông tin HV'!O35 | L41: ='Thông tin HV'!P35
A42: 33 | B42: =PROPER(TRIM(LEFT(TRIM('Thông tin HV'!C36),LEN(TRIM('Thông tin HV'!C36))-LEN(C42)))) | C42: =PROPER(TRIM(RIGHT(SUBSTITUTE(TRIM('Thông tin HV'!C36)," ",REPT(" ",100)),100))) | D42: ='Thông tin HV'!D36 | E42: Nữ | F42: Xê Đăng | I42: ='Thông tin HV'!K36&"/12" | J42: 3 | K42: ='Thông tin HV'!O36 | L42: ='Thông tin HV'!P36
B43: =PROPER(TRIM(LEFT(TRIM('Thông tin HV'!C37),LEN(TRIM('Thông tin HV'!C37))-LEN(C43)))) | C43: =PROPER(TRIM(RIGHT(SUBSTITUTE(TRIM('Thông tin HV'!C37)," ",REPT(" ",100)),100))) | D43: ='Thông tin HV'!D37 | I43: ='Thông tin HV'!K37&"/12"
...

Sheet DSTN-TT
B1: SỞ GIÁO DỤC VÀ ĐÀO TẠO TỈNH QUẢNG NGÃI | K1: CỘNG HÒA XÃ HỘI CHỦ NGHĨA VIỆT NAM
B2: TRUNG TÂM GDNN-GDTX KHU VỰC ĐĂK HÀ | K2: Độc lập - Tự do - Hạnh phúc
A5: DANH SÁCH TRÍCH NGANG HỌC VIÊN
A6: ="Tham gia lớp Đào tạo Nghề: "&UPPER('KHÓA HỌC'!D5)&"; Khóa: "&'KHÓA HỌC'!D3&"; Năm "&'KHÓA HỌC'!D4
A7: Địa điểm mở lớp: ....................................................................................................
A8: (Danh sách kèm theo Quyết định số: /QĐ-GDNN-GDTX ngày tháng năm 2026 của Giám đốc Trung tâm GDNN-GDTX khu vực Đăk Hà)
A9: Số TT | B9: Họ và tên | D9: Ngày, tháng, năm sinh | E9: Giới tính | F9: Dân tộc | G9: Thanh niên | H9: Thanh niên DTTS | I9: Trình độ văn hóa | J9: Nhóm đối tượng | K9: Nguyên quán | L9: Nơi cư trú | M9: Ghi chú
A10: 1 | B10: =PROPER(TRIM(LEFT(TRIM('Thông tin HV'!C4),LEN(TRIM('Thông tin HV'!C4))-LEN(C10)))) | C10: =PROPER(TRIM(RIGHT(SUBSTITUTE(TRIM('Thông tin HV'!C4)," ",REPT(" ",100)),100))) | D10: ='Thông tin HV'!D4 | E10: ='Thông tin HV'!E4 | F10: ='Thông tin HV'!G4 | G10: ='Thông tin HV'!I4 | H10: ='Thông tin HV'!J4 | I10: ='Thông tin HV'!K4&"/12" | J10: ='Thông tin HV'!M4 | K10: ='Thông tin HV'!O4 | L10: ='Thông tin HV'!P4
A11: 2 | B11: =PROPER(TRIM(LEFT(TRIM('Thông tin HV'!C5),LEN(TRIM('Thông tin HV'!C5))-LEN(C11)))) | C11: =PROPER(TRIM(RIGHT(SUBSTITUTE(TRIM('Thông tin HV'!C5)," ",REPT(" ",100)),100))) | D11: ='Thông tin HV'!D5 | E11: Nam | F11: ='Thông tin HV'!G5 | G11: ='Thông tin HV'!I5 | H11: ='Thông tin HV'!J5 | I11: ='Thông tin HV'!K5&"/12" | J11: ='Thông tin HV'!M5 | K11: ='Thông tin HV'!O5 | L11: ='Thông tin HV'!P5
A12: 3 | B12: =PROPER(TRIM(LEFT(TRIM('Thông tin HV'!C6),LEN(TRIM('Thông tin HV'!C6))-LEN(C12)))) | C12: =PROPER(TRIM(RIGHT(SUBSTITUTE(TRIM('Thông tin HV'!C6)," ",REPT(" ",100)),100))) | D12: ='Thông tin HV'!D6 | E12: Nam | F12: ='Thông tin HV'!G6 | G12: ='Thông tin HV'!I6 | H12: ='Thông tin HV'!J6 | I12: ='Thông tin HV'!K6&"/12" | J12: ='Thông tin HV'!M6 | K12: ='Thông tin HV'!O6 | L12: ='Thông tin HV'!P6
A13: 4 | B13: =PROPER(TRIM(LEFT(TRIM('Thông tin HV'!C7),LEN(TRIM('Thông tin HV'!C7))-LEN(C13)))) | C13: =PROPER(TRIM(RIGHT(SUBSTITUTE(TRIM('Thông tin HV'!C7)," ",REPT(" ",100)),100))) | D13: ='Thông tin HV'!D7 | E13: Nam | F13: ='Thông tin HV'!G7 | G13: ='Thông tin HV'!I7 | H13: ='Thông tin HV'!J7 | I13: ='Thông tin HV'!K7&"/12" | J13: ='Thông tin HV'!M7 | K13: ='Thông tin HV'!O7 | L13: ='Thông tin HV'!P7
A14: 5 | B14: =PROPER(TRIM(LEFT(TRIM('Thông tin HV'!C8),LEN(TRIM('Thông tin HV'!C8))-LEN(C14)))) | C14: =PROPER(TRIM(RIGHT(SUBSTITUTE(TRIM('Thông tin HV'!C8)," ",REPT(" ",100)),100))) | D14: ='Thông tin HV'!D8 | E14: Nam | F14: ='Thông tin HV'!G8 | G14: ='Thông tin HV'!I8 | H14: ='Thông tin HV'!J8 | I14: ='Thông tin HV'!K8&"/12" | J14: ='Thông tin HV'!M8 | K14: ='Thông tin HV'!O8 | L14: ='Thông tin HV'!P8
A15: 6 | B15: =PROPER(TRIM(LEFT(TRIM('Thông tin HV'!C9),LEN(TRIM('Thông tin HV'!C9))-LEN(C15)))) | C15: =PROPER(TRIM(RIGHT(SUBSTITUTE(TRIM('Thông tin HV'!C9)," ",REPT(" ",100)),100))) | D15: ='Thông tin HV'!D9 | E15: Nam | F15: ='Thông tin HV'!G9 | G15: ='Thông tin HV'!I9 | H15: ='Thông tin HV'!J9 | I15: ='Thông tin HV'!K9&"/12" | J15: ='Thông tin HV'!M9 | K15: ='Thông tin HV'!O9 | L15: ='Thông tin HV'!P9
